{
  "version": "4.28.0",
  "time": 3.078,
  "errors": [],
  "tasks": [
    {
      "resource": {
        "name": "ft_receita_v2018",
        "title": "Receita v2",
        "path": "data/ft_receita_v2018.csv.gz",
        "schema": {
          "fields": [
            {
              "name": "id_tempo",
              "title": "Tempo - Chave",
              "type": "integer",
              "format": "default",
              "bareNumber": true,
              "constraints": {
                "required": true,
                "unique": false
              }
            },
            {
              "name": "id_unidade_orc",
              "title": "Unidade Orçamentária - Chave",
              "type": "integer",
              "format": "default",
              "bareNumber": true,
              "constraints": {
                "required": true,
                "unique": false
              }
            },
            {
              "name": "id_origem",
              "title": "Origem - Chave",
              "type": "integer",
              "format": "default",
              "bareNumber": true,
              "constraints": {
                "required": true,
                "unique": false
              }
            },
            {
              "name": "id_especie",
              "title": "Espécie - Chave",
              "type": "integer",
              "format": "default",
              "bareNumber": true,
              "constraints": {
                "required": true,
                "unique": false
              }
            },
            {
              "name": "id_desdobramento_1",
              "title": "Desdobramento 1 - Chave",
              "type": "integer",
              "format": "default",
              "bareNumber": true,
              "constraints": {
                "required": true,
                "unique": false
              }
            },
            {
              "name": "id_desdobramento_2",
              "title": "Desdobramento 2 - Chave",
              "type": "integer",
              "format": "default",
              "bareNumber": true,
              "constraints": {
                "required": true,
                "unique": false
              }
            },
            {
              "name": "id_desdobramento_3",
              "title": "Desdobramento 3 - Chave",
              "type": "integer",
              "format": "default",
              "bareNumber": true,
              "constraints": {
                "required": true,
                "unique": false
              }
            },
            {
              "name": "id_tipo",
              "title": "Tipo de Receita - Chave",
              "type": "integer",
              "format": "default",
              "bareNumber": true,
              "constraints": {
                "required": true,
                "unique": false
              }
            },
            {
              "name": "id_item",
              "title": "Item da Receita - Chave",
              "type": "integer",
              "format": "default",
              "bareNumber": true,
              "constraints": {
                "required": true,
                "unique": false
              }
            },
            {
              "name": "id_subitem",
              "title": "Subitem da Receita - Chave",
              "type": "integer",
              "format": "default",
              "bareNumber": true,
              "constraints": {
                "required": true,
                "unique": false
              }
            },
            {
              "name": "id_fonte",
              "title": "Fonte de Recurso - Chave",
              "type": "integer",
              "format": "default",
              "bareNumber": true,
              "constraints": {
                "required": true,
                "unique": false
              }
            },
            {
              "name": "cd_fonte",
              "title": "Fonte de Recurso - Código",
              "type": "string",
              "format": "default",
              "description": "Código da fonte de recurso origem da receita orçamentária.\n",
              "constraints": {
                "required": true,
                "enum": [
                  "10",
                  "11",
                  "12",
                  "13",
                  "20",
                  "21",
                  "22",
                  "23",
                  "24",
                  "25",
                  "26",
                  "27",
                  "29",
                  "30",
                  "31",
                  "32",
                  "33",
                  "36",
                  "37",
                  "38",
                  "39",
                  "40",
                  "42",
                  "43",
                  "44",
                  "45",
                  "46",
                  "47",
                  "48",
                  "49",
                  "50",
                  "51",
                  "52",
                  "53",
                  "54",
                  "55",
                  "56",
                  "57",
                  "58",
                  "59",
                  "60",
                  "61",
                  "70",
                  "71",
                  "72",
                  "73",
                  "74",
                  "75",
                  "77",
                  "78",
                  "81",
                  "82",
                  "83",
                  "84",
                  "85",
                  "86",
                  "87",
                  "88",
                  "89",
                  "91",
                  "92",
                  "93",
                  "94",
                  "95",
                  "96",
                  "97",
                  "99"
                ]
              }
            },
            {
              "name": "cd_classificacao_rec",
              "type": "string",
              "format": "default",
              "Código completo da classificação econômica da receita.Os números representam, da esquerda para a direita": [
                "1º dígito - Categoria econômica;",
                "2º dígito -Origem;",
                "3º dígito -Espécie;",
                "4º a 7º dígito -Desdobramentos para identificação de peculiaridades da receita;",
                "8º dígito - Tipo da receita;",
                "9º e 10º dígito - Item da receita e",
                "11º a 13º dígito - Subitem da receita."
              ],
              "constraints": {
                "required": true
              }
            },
            {
              "name": "ano_particao",
              "title": "Ano de Partição",
              "type": "year",
              "format": "default",
              "constraints": {
                "required": true
              }
            },
            {
              "name": "vr_efetivado",
              "title": "Valor Efetivado",
              "type": "number",
              "format": "default",
              "decimalChar": ".",
              "bareNumber": true,
              "description": "Valor, em reais, da receita orçamentária efetivada ajustada.\n",
              "constraints": {
                "required": true
              }
            }
          ],
          "missingValues": [
            ""
          ],
          "foreignKeys": [
            {
              "fields": [
                "id_especie"
              ],
              "reference": {
                "fields": [
                  "id_especie"
                ],
                "resource": "dm_especie_rec"
              }
            },
            {
              "fields": [
                "id_tempo"
              ],
              "reference": {
                "fields": [
                  "id_tempo"
                ],
                "resource": "dm_tempo_mensal"
              }
            },
            {
              "fields": [
                "id_desdobramento_3"
              ],
              "reference": {
                "fields": [
                  "id_desdobramento_3"
                ],
                "resource": "dm_desdobramento_3_rec"
              }
            },
            {
              "fields": [
                "id_desdobramento_1"
              ],
              "reference": {
                "fields": [
                  "id_desdobramento_1"
                ],
                "resource": "dm_desdobramento_1_rec"
              }
            },
            {
              "fields": [
                "id_origem"
              ],
              "reference": {
                "fields": [
                  "id_origem"
                ],
                "resource": "dm_origem_rec"
              }
            },
            {
              "fields": [
                "id_fonte"
              ],
              "reference": {
                "fields": [
                  "id_fonte"
                ],
                "resource": "dm_fonte_rec"
              }
            },
            {
              "fields": [
                "id_tipo"
              ],
              "reference": {
                "fields": [
                  "id_tipo"
                ],
                "resource": "dm_tipo_rec"
              }
            },
            {
              "fields": [
                "id_subitem"
              ],
              "reference": {
                "fields": [
                  "id_subitem"
                ],
                "resource": "dm_subitem_rec"
              }
            },
            {
              "fields": [
                "id_desdobramento_2"
              ],
              "reference": {
                "fields": [
                  "id_desdobramento_2"
                ],
                "resource": "dm_desdobramento_2_rec"
              }
            },
            {
              "fields": [
                "id_unidade_orc"
              ],
              "reference": {
                "fields": [
                  "id_unidade_orc"
                ],
                "resource": "dm_unidade_orc"
              }
            },
            {
              "fields": [
                "id_item"
              ],
              "reference": {
                "fields": [
                  "id_item"
                ],
                "resource": "dm_item_rec"
              }
            }
          ]
        },
        "sources": [
          {
            "title": "Tabela origem no schema AGE7 no banco de dados do Portal da Transparência",
            "table": "ft_receita_v2018"
          }
        ],
        "format": "csv",
        "mediatype": "text/csv",
        "encoding": "utf-8-sig",
        "dialect": {
          "delimiter": ";"
        },
        "profile": "tabular-data-resource",
        "scheme": "file",
        "hashing": "md5",
        "compression": "gz",
        "stats": {
          "hash": "ffca266a017a0d9a7548361ddc962afc",
          "bytes": 517885,
          "fields": 15,
          "rows": 35756
        }
      },
      "time": 3.078,
      "scope": [
        "hash-count-error",
        "byte-count-error",
        "field-count-error",
        "row-count-error",
        "blank-header",
        "extra-label",
        "missing-label",
        "blank-label",
        "duplicate-label",
        "incorrect-label",
        "blank-row",
        "primary-key-error",
        "foreign-key-error",
        "extra-cell",
        "missing-cell",
        "type-error",
        "constraint-error",
        "unique-error"
      ],
      "partial": false,
      "errors": [
        {
          "cells": [
            "1002",
            "4247",
            "535",
            "793",
            "964",
            "2121",
            "4045",
            "7453",
            "15654",
            "16366",
            "4",
            "23",
            "9118022302000",
            "2022",
            "0.00"
          ],
          "rowNumber": 4246,
          "rowPosition": 4247,
          "code": "foreign-key-error",
          "name": "ForeignKey Error",
          "tags": [
            "#table",
            "#row"
          ],
          "note": "for \"id_desdobramento_3\": values \"4045\" not found in the lookup table \"dm_desdobramento_3_rec\" as \"id_desdobramento_3\"",
          "message": "Row at position \"4247\" violates the foreign key: for \"id_desdobramento_3\": values \"4045\" not found in the lookup table \"dm_desdobramento_3_rec\" as \"id_desdobramento_3\"",
          "description": "Values in the foreign key fields should exist in the reference table"
        },
        {
          "cells": [
            "1002",
            "4247",
            "535",
            "793",
            "964",
            "2121",
            "4045",
            "7453",
            "15654",
            "16366",
            "4",
            "23",
            "9118022302000",
            "2022",
            "0.00"
          ],
          "rowNumber": 4246,
          "rowPosition": 4247,
          "code": "foreign-key-error",
          "name": "ForeignKey Error",
          "tags": [
            "#table",
            "#row"
          ],
          "note": "for \"id_desdobramento_2\": values \"2121\" not found in the lookup table \"dm_desdobramento_2_rec\" as \"id_desdobramento_2\"",
          "message": "Row at position \"4247\" violates the foreign key: for \"id_desdobramento_2\": values \"2121\" not found in the lookup table \"dm_desdobramento_2_rec\" as \"id_desdobramento_2\"",
          "description": "Values in the foreign key fields should exist in the reference table"
        },
        {
          "cells": [
            "999",
            "4247",
            "544",
            "802",
            "974",
            "2129",
            "4054",
            "7469",
            "15947",
            "16794",
            "4",
            "23",
            "9118022402000",
            "2022",
            "0.00"
          ],
          "rowNumber": 4247,
          "rowPosition": 4248,
          "code": "foreign-key-error",
          "name": "ForeignKey Error",
          "tags": [
            "#table",
            "#row"
          ],
          "note": "for \"id_desdobramento_3\": values \"4054\" not found in the lookup table \"dm_desdobramento_3_rec\" as \"id_desdobramento_3\"",
          "message": "Row at position \"4248\" violates the foreign key: for \"id_desdobramento_3\": values \"4054\" not found in the lookup table \"dm_desdobramento_3_rec\" as \"id_desdobramento_3\"",
          "description": "Values in the foreign key fields should exist in the reference table"
        },
        {
          "cells": [
            "999",
            "4247",
            "544",
            "802",
            "974",
            "2129",
            "4054",
            "7469",
            "15947",
            "16794",
            "4",
            "23",
            "9118022402000",
            "2022",
            "0.00"
          ],
          "rowNumber": 4247,
          "rowPosition": 4248,
          "code": "foreign-key-error",
          "name": "ForeignKey Error",
          "tags": [
            "#table",
            "#row"
          ],
          "note": "for \"id_desdobramento_2\": values \"2129\" not found in the lookup table \"dm_desdobramento_2_rec\" as \"id_desdobramento_2\"",
          "message": "Row at position \"4248\" violates the foreign key: for \"id_desdobramento_2\": values \"2129\" not found in the lookup table \"dm_desdobramento_2_rec\" as \"id_desdobramento_2\"",
          "description": "Values in the foreign key fields should exist in the reference table"
        },
        {
          "cells": [
            "1000",
            "4224",
            "540",
            "798",
            "969",
            "2124",
            "4052",
            "7467",
            "15941",
            "16785",
            "54",
            "20",
            "9118012102000",
            "2022",
            "-241113811.08"
          ],
          "rowNumber": 4711,
          "rowPosition": 4712,
          "code": "foreign-key-error",
          "name": "ForeignKey Error",
          "tags": [
            "#table",
            "#row"
          ],
          "note": "for \"id_desdobramento_3\": values \"4052\" not found in the lookup table \"dm_desdobramento_3_rec\" as \"id_desdobramento_3\"",
          "message": "Row at position \"4712\" violates the foreign key: for \"id_desdobramento_3\": values \"4052\" not found in the lookup table \"dm_desdobramento_3_rec\" as \"id_desdobramento_3\"",
          "description": "Values in the foreign key fields should exist in the reference table"
        },
        {
          "cells": [
            "1000",
            "4224",
            "540",
            "798",
            "969",
            "2124",
            "4052",
            "7467",
            "15941",
            "16785",
            "54",
            "20",
            "9118012102000",
            "2022",
            "-241113811.08"
          ],
          "rowNumber": 4711,
          "rowPosition": 4712,
          "code": "foreign-key-error",
          "name": "ForeignKey Error",
          "tags": [
            "#table",
            "#row"
          ],
          "note": "for \"id_desdobramento_2\": values \"2124\" not found in the lookup table \"dm_desdobramento_2_rec\" as \"id_desdobramento_2\"",
          "message": "Row at position \"4712\" violates the foreign key: for \"id_desdobramento_2\": values \"2124\" not found in the lookup table \"dm_desdobramento_2_rec\" as \"id_desdobramento_2\"",
          "description": "Values in the foreign key fields should exist in the reference table"
        },
        {
          "cells": [
            "1002",
            "4224",
            "538",
            "796",
            "972",
            "2123",
            "4051",
            "7466",
            "15943",
            "16787",
            "54",
            "20",
            "9718016101002",
            "2022",
            "-13919549.27"
          ],
          "rowNumber": 4712,
          "rowPosition": 4713,
          "code": "foreign-key-error",
          "name": "ForeignKey Error",
          "tags": [
            "#table",
            "#row"
          ],
          "note": "for \"id_desdobramento_3\": values \"4051\" not found in the lookup table \"dm_desdobramento_3_rec\" as \"id_desdobramento_3\"",
          "message": "Row at position \"4713\" violates the foreign key: for \"id_desdobramento_3\": values \"4051\" not found in the lookup table \"dm_desdobramento_3_rec\" as \"id_desdobramento_3\"",
          "description": "Values in the foreign key fields should exist in the reference table"
        },
        {
          "cells": [
            "1002",
            "4224",
            "538",
            "796",
            "972",
            "2123",
            "4051",
            "7466",
            "15943",
            "16787",
            "54",
            "20",
            "9718016101002",
            "2022",
            "-13919549.27"
          ],
          "rowNumber": 4712,
          "rowPosition": 4713,
          "code": "foreign-key-error",
          "name": "ForeignKey Error",
          "tags": [
            "#table",
            "#row"
          ],
          "note": "for \"id_desdobramento_2\": values \"2123\" not found in the lookup table \"dm_desdobramento_2_rec\" as \"id_desdobramento_2\"",
          "message": "Row at position \"4713\" violates the foreign key: for \"id_desdobramento_2\": values \"2123\" not found in the lookup table \"dm_desdobramento_2_rec\" as \"id_desdobramento_2\"",
          "description": "Values in the foreign key fields should exist in the reference table"
        },
        {
          "cells": [
            "1002",
            "4224",
            "535",
            "793",
            "964",
            "2121",
            "4045",
            "7453",
            "15654",
            "16366",
            "4",
            "23",
            "9118022302000",
            "2022",
            "-2953.19"
          ],
          "rowNumber": 4715,
          "rowPosition": 4716,
          "code": "foreign-key-error",
          "name": "ForeignKey Error",
          "tags": [
            "#table",
            "#row"
          ],
          "note": "for \"id_desdobramento_3\": values \"4045\" not found in the lookup table \"dm_desdobramento_3_rec\" as \"id_desdobramento_3\"",
          "message": "Row at position \"4716\" violates the foreign key: for \"id_desdobramento_3\": values \"4045\" not found in the lookup table \"dm_desdobramento_3_rec\" as \"id_desdobramento_3\"",
          "description": "Values in the foreign key fields should exist in the reference table"
        },
        {
          "cells": [
            "1002",
            "4224",
            "535",
            "793",
            "964",
            "2121",
            "4045",
            "7453",
            "15654",
            "16366",
            "4",
            "23",
            "9118022302000",
            "2022",
            "-2953.19"
          ],
          "rowNumber": 4715,
          "rowPosition": 4716,
          "code": "foreign-key-error",
          "name": "ForeignKey Error",
          "tags": [
            "#table",
            "#row"
          ],
          "note": "for \"id_desdobramento_2\": values \"2121\" not found in the lookup table \"dm_desdobramento_2_rec\" as \"id_desdobramento_2\"",
          "message": "Row at position \"4716\" violates the foreign key: for \"id_desdobramento_2\": values \"2121\" not found in the lookup table \"dm_desdobramento_2_rec\" as \"id_desdobramento_2\"",
          "description": "Values in the foreign key fields should exist in the reference table"
        },
        {
          "cells": [
            "999",
            "4247",
            "535",
            "793",
            "964",
            "2121",
            "4045",
            "7453",
            "15654",
            "16366",
            "4",
            "23",
            "9118022302000",
            "2022",
            "0.00"
          ],
          "rowNumber": 4716,
          "rowPosition": 4717,
          "code": "foreign-key-error",
          "name": "ForeignKey Error",
          "tags": [
            "#table",
            "#row"
          ],
          "note": "for \"id_desdobramento_3\": values \"4045\" not found in the lookup table \"dm_desdobramento_3_rec\" as \"id_desdobramento_3\"",
          "message": "Row at position \"4717\" violates the foreign key: for \"id_desdobramento_3\": values \"4045\" not found in the lookup table \"dm_desdobramento_3_rec\" as \"id_desdobramento_3\"",
          "description": "Values in the foreign key fields should exist in the reference table"
        },
        {
          "cells": [
            "999",
            "4247",
            "535",
            "793",
            "964",
            "2121",
            "4045",
            "7453",
            "15654",
            "16366",
            "4",
            "23",
            "9118022302000",
            "2022",
            "0.00"
          ],
          "rowNumber": 4716,
          "rowPosition": 4717,
          "code": "foreign-key-error",
          "name": "ForeignKey Error",
          "tags": [
            "#table",
            "#row"
          ],
          "note": "for \"id_desdobramento_2\": values \"2121\" not found in the lookup table \"dm_desdobramento_2_rec\" as \"id_desdobramento_2\"",
          "message": "Row at position \"4717\" violates the foreign key: for \"id_desdobramento_2\": values \"2121\" not found in the lookup table \"dm_desdobramento_2_rec\" as \"id_desdobramento_2\"",
          "description": "Values in the foreign key fields should exist in the reference table"
        },
        {
          "cells": [
            "991",
            "4144",
            "528",
            "50",
            "963",
            "2112",
            "4025",
            "7430",
            "15648",
            "16364",
            "4",
            "23",
            "9118022202000",
            "2021",
            "-56770.27"
          ],
          "rowNumber": 4722,
          "rowPosition": 4723,
          "code": "foreign-key-error",
          "name": "ForeignKey Error",
          "tags": [
            "#table",
            "#row"
          ],
          "note": "for \"id_desdobramento_3\": values \"4025\" not found in the lookup table \"dm_desdobramento_3_rec\" as \"id_desdobramento_3\"",
          "message": "Row at position \"4723\" violates the foreign key: for \"id_desdobramento_3\": values \"4025\" not found in the lookup table \"dm_desdobramento_3_rec\" as \"id_desdobramento_3\"",
          "description": "Values in the foreign key fields should exist in the reference table"
        },
        {
          "cells": [
            "991",
            "4144",
            "528",
            "50",
            "963",
            "2112",
            "4025",
            "7430",
            "15648",
            "16364",
            "4",
            "23",
            "9118022202000",
            "2021",
            "-56770.27"
          ],
          "rowNumber": 4722,
          "rowPosition": 4723,
          "code": "foreign-key-error",
          "name": "ForeignKey Error",
          "tags": [
            "#table",
            "#row"
          ],
          "note": "for \"id_desdobramento_2\": values \"2112\" not found in the lookup table \"dm_desdobramento_2_rec\" as \"id_desdobramento_2\"",
          "message": "Row at position \"4723\" violates the foreign key: for \"id_desdobramento_2\": values \"2112\" not found in the lookup table \"dm_desdobramento_2_rec\" as \"id_desdobramento_2\"",
          "description": "Values in the foreign key fields should exist in the reference table"
        },
        {
          "cells": [
            "1000",
            "4224",
            "531",
            "792",
            "966",
            "2118",
            "4036",
            "7447",
            "15648",
            "16364",
            "4",
            "23",
            "9118022202000",
            "2022",
            "-55993.89"
          ],
          "rowNumber": 7080,
          "rowPosition": 7081,
          "code": "foreign-key-error",
          "name": "ForeignKey Error",
          "tags": [
            "#table",
            "#row"
          ],
          "note": "for \"id_desdobramento_3\": values \"4036\" not found in the lookup table \"dm_desdobramento_3_rec\" as \"id_desdobramento_3\"",
          "message": "Row at position \"7081\" violates the foreign key: for \"id_desdobramento_3\": values \"4036\" not found in the lookup table \"dm_desdobramento_3_rec\" as \"id_desdobramento_3\"",
          "description": "Values in the foreign key fields should exist in the reference table"
        },
        {
          "cells": [
            "1000",
            "4224",
            "531",
            "792",
            "966",
            "2118",
            "4036",
            "7447",
            "15648",
            "16364",
            "4",
            "23",
            "9118022202000",
            "2022",
            "-55993.89"
          ],
          "rowNumber": 7080,
          "rowPosition": 7081,
          "code": "foreign-key-error",
          "name": "ForeignKey Error",
          "tags": [
            "#table",
            "#row"
          ],
          "note": "for \"id_desdobramento_2\": values \"2118\" not found in the lookup table \"dm_desdobramento_2_rec\" as \"id_desdobramento_2\"",
          "message": "Row at position \"7081\" violates the foreign key: for \"id_desdobramento_2\": values \"2118\" not found in the lookup table \"dm_desdobramento_2_rec\" as \"id_desdobramento_2\"",
          "description": "Values in the foreign key fields should exist in the reference table"
        },
        {
          "cells": [
            "990",
            "4144",
            "528",
            "50",
            "963",
            "2112",
            "4025",
            "7433",
            "15654",
            "16366",
            "4",
            "23",
            "9118022302000",
            "2021",
            "-157001.55"
          ],
          "rowNumber": 7814,
          "rowPosition": 7815,
          "code": "foreign-key-error",
          "name": "ForeignKey Error",
          "tags": [
            "#table",
            "#row"
          ],
          "note": "for \"id_desdobramento_3\": values \"4025\" not found in the lookup table \"dm_desdobramento_3_rec\" as \"id_desdobramento_3\"",
          "message": "Row at position \"7815\" violates the foreign key: for \"id_desdobramento_3\": values \"4025\" not found in the lookup table \"dm_desdobramento_3_rec\" as \"id_desdobramento_3\"",
          "description": "Values in the foreign key fields should exist in the reference table"
        },
        {
          "cells": [
            "990",
            "4144",
            "528",
            "50",
            "963",
            "2112",
            "4025",
            "7433",
            "15654",
            "16366",
            "4",
            "23",
            "9118022302000",
            "2021",
            "-157001.55"
          ],
          "rowNumber": 7814,
          "rowPosition": 7815,
          "code": "foreign-key-error",
          "name": "ForeignKey Error",
          "tags": [
            "#table",
            "#row"
          ],
          "note": "for \"id_desdobramento_2\": values \"2112\" not found in the lookup table \"dm_desdobramento_2_rec\" as \"id_desdobramento_2\"",
          "message": "Row at position \"7815\" violates the foreign key: for \"id_desdobramento_2\": values \"2112\" not found in the lookup table \"dm_desdobramento_2_rec\" as \"id_desdobramento_2\"",
          "description": "Values in the foreign key fields should exist in the reference table"
        },
        {
          "cells": [
            "991",
            "4144",
            "528",
            "50",
            "963",
            "2112",
            "4025",
            "7431",
            "15652",
            "16362",
            "4",
            "23",
            "9118022402000",
            "2021",
            "-31.93"
          ],
          "rowNumber": 7815,
          "rowPosition": 7816,
          "code": "foreign-key-error",
          "name": "ForeignKey Error",
          "tags": [
            "#table",
            "#row"
          ],
          "note": "for \"id_desdobramento_3\": values \"4025\" not found in the lookup table \"dm_desdobramento_3_rec\" as \"id_desdobramento_3\"",
          "message": "Row at position \"7816\" violates the foreign key: for \"id_desdobramento_3\": values \"4025\" not found in the lookup table \"dm_desdobramento_3_rec\" as \"id_desdobramento_3\"",
          "description": "Values in the foreign key fields should exist in the reference table"
        },
        {
          "cells": [
            "991",
            "4144",
            "528",
            "50",
            "963",
            "2112",
            "4025",
            "7431",
            "15652",
            "16362",
            "4",
            "23",
            "9118022402000",
            "2021",
            "-31.93"
          ],
          "rowNumber": 7815,
          "rowPosition": 7816,
          "code": "foreign-key-error",
          "name": "ForeignKey Error",
          "tags": [
            "#table",
            "#row"
          ],
          "note": "for \"id_desdobramento_2\": values \"2112\" not found in the lookup table \"dm_desdobramento_2_rec\" as \"id_desdobramento_2\"",
          "message": "Row at position \"7816\" violates the foreign key: for \"id_desdobramento_2\": values \"2112\" not found in the lookup table \"dm_desdobramento_2_rec\" as \"id_desdobramento_2\"",
          "description": "Values in the foreign key fields should exist in the reference table"
        },
        {
          "cells": [
            "974",
            "4032",
            "10",
            "145",
            "173",
            "437",
            "4020",
            "7427",
            "15615",
            "16001",
            "355",
            "92",
            "1718039101000",
            "2020",
            "186005199.05"
          ],
          "rowNumber": 7851,
          "rowPosition": 7852,
          "code": "foreign-key-error",
          "name": "ForeignKey Error",
          "tags": [
            "#table",
            "#row"
          ],
          "note": "for \"id_desdobramento_3\": values \"4020\" not found in the lookup table \"dm_desdobramento_3_rec\" as \"id_desdobramento_3\"",
          "message": "Row at position \"7852\" violates the foreign key: for \"id_desdobramento_3\": values \"4020\" not found in the lookup table \"dm_desdobramento_3_rec\" as \"id_desdobramento_3\"",
          "description": "Values in the foreign key fields should exist in the reference table"
        },
        {
          "cells": [
            "978",
            "4018",
            "527",
            "75",
            "962",
            "68",
            "4021",
            "7428",
            "15618",
            "16014",
            "25",
            "60",
            "9321001101000",
            "2020",
            "-15402.28"
          ],
          "rowNumber": 10477,
          "rowPosition": 10478,
          "code": "foreign-key-error",
          "name": "ForeignKey Error",
          "tags": [
            "#table",
            "#row"
          ],
          "note": "for \"id_desdobramento_3\": values \"4021\" not found in the lookup table \"dm_desdobramento_3_rec\" as \"id_desdobramento_3\"",
          "message": "Row at position \"10478\" violates the foreign key: for \"id_desdobramento_3\": values \"4021\" not found in the lookup table \"dm_desdobramento_3_rec\" as \"id_desdobramento_3\"",
          "description": "Values in the foreign key fields should exist in the reference table"
        },
        {
          "cells": [
            "2265",
            "4032",
            "16",
            "145",
            "173",
            "199",
            "4020",
            "7427",
            "15616",
            "15997",
            "356",
            "93",
            "2418039101000",
            "2020",
            "0.00"
          ],
          "rowNumber": 12226,
          "rowPosition": 12227,
          "code": "foreign-key-error",
          "name": "ForeignKey Error",
          "tags": [
            "#table",
            "#row"
          ],
          "note": "for \"id_desdobramento_3\": values \"4020\" not found in the lookup table \"dm_desdobramento_3_rec\" as \"id_desdobramento_3\"",
          "message": "Row at position \"12227\" violates the foreign key: for \"id_desdobramento_3\": values \"4020\" not found in the lookup table \"dm_desdobramento_3_rec\" as \"id_desdobramento_3\"",
          "description": "Values in the foreign key fields should exist in the reference table"
        },
        {
          "cells": [
            "1002",
            "4247",
            "530",
            "794",
            "965",
            "2119",
            "4042",
            "7460",
            "15651",
            "16365",
            "4",
            "23",
            "9118022102000",
            "2022",
            "0.00"
          ],
          "rowNumber": 19364,
          "rowPosition": 19365,
          "code": "foreign-key-error",
          "name": "ForeignKey Error",
          "tags": [
            "#table",
            "#row"
          ],
          "note": "for \"id_desdobramento_3\": values \"4042\" not found in the lookup table \"dm_desdobramento_3_rec\" as \"id_desdobramento_3\"",
          "message": "Row at position \"19365\" violates the foreign key: for \"id_desdobramento_3\": values \"4042\" not found in the lookup table \"dm_desdobramento_3_rec\" as \"id_desdobramento_3\"",
          "description": "Values in the foreign key fields should exist in the reference table"
        },
        {
          "cells": [
            "1002",
            "4247",
            "530",
            "794",
            "965",
            "2119",
            "4042",
            "7460",
            "15651",
            "16365",
            "4",
            "23",
            "9118022102000",
            "2022",
            "0.00"
          ],
          "rowNumber": 19364,
          "rowPosition": 19365,
          "code": "foreign-key-error",
          "name": "ForeignKey Error",
          "tags": [
            "#table",
            "#row"
          ],
          "note": "for \"id_desdobramento_2\": values \"2119\" not found in the lookup table \"dm_desdobramento_2_rec\" as \"id_desdobramento_2\"",
          "message": "Row at position \"19365\" violates the foreign key: for \"id_desdobramento_2\": values \"2119\" not found in the lookup table \"dm_desdobramento_2_rec\" as \"id_desdobramento_2\"",
          "description": "Values in the foreign key fields should exist in the reference table"
        },
        {
          "cells": [
            "986",
            "4130",
            "527",
            "75",
            "962",
            "68",
            "4023",
            "7429",
            "15635",
            "16272",
            "25",
            "60",
            "9321001101000",
            "2021",
            "-1535.81"
          ],
          "rowNumber": 19723,
          "rowPosition": 19724,
          "code": "foreign-key-error",
          "name": "ForeignKey Error",
          "tags": [
            "#table",
            "#row"
          ],
          "note": "for \"id_desdobramento_3\": values \"4023\" not found in the lookup table \"dm_desdobramento_3_rec\" as \"id_desdobramento_3\"",
          "message": "Row at position \"19724\" violates the foreign key: for \"id_desdobramento_3\": values \"4023\" not found in the lookup table \"dm_desdobramento_3_rec\" as \"id_desdobramento_3\"",
          "description": "Values in the foreign key fields should exist in the reference table"
        },
        {
          "cells": [
            "999",
            "4224",
            "16",
            "146",
            "153",
            "2120",
            "4026",
            "7443",
            "15844",
            "16750",
            "98",
            "74",
            "2448019107001",
            "2022",
            "0.00"
          ],
          "rowNumber": 20089,
          "rowPosition": 20090,
          "code": "foreign-key-error",
          "name": "ForeignKey Error",
          "tags": [
            "#table",
            "#row"
          ],
          "note": "for \"id_desdobramento_3\": values \"4026\" not found in the lookup table \"dm_desdobramento_3_rec\" as \"id_desdobramento_3\"",
          "message": "Row at position \"20090\" violates the foreign key: for \"id_desdobramento_3\": values \"4026\" not found in the lookup table \"dm_desdobramento_3_rec\" as \"id_desdobramento_3\"",
          "description": "Values in the foreign key fields should exist in the reference table"
        },
        {
          "cells": [
            "999",
            "4224",
            "16",
            "146",
            "153",
            "2120",
            "4026",
            "7443",
            "15844",
            "16750",
            "98",
            "74",
            "2448019107001",
            "2022",
            "0.00"
          ],
          "rowNumber": 20089,
          "rowPosition": 20090,
          "code": "foreign-key-error",
          "name": "ForeignKey Error",
          "tags": [
            "#table",
            "#row"
          ],
          "note": "for \"id_desdobramento_2\": values \"2120\" not found in the lookup table \"dm_desdobramento_2_rec\" as \"id_desdobramento_2\"",
          "message": "Row at position \"20090\" violates the foreign key: for \"id_desdobramento_2\": values \"2120\" not found in the lookup table \"dm_desdobramento_2_rec\" as \"id_desdobramento_2\"",
          "description": "Values in the foreign key fields should exist in the reference table"
        },
        {
          "cells": [
            "1000",
            "4271",
            "16",
            "146",
            "153",
            "2120",
            "4026",
            "7443",
            "15716",
            "16461",
            "96",
            "70",
            "2448019118001",
            "2022",
            "6152446.00"
          ],
          "rowNumber": 20364,
          "rowPosition": 20365,
          "code": "foreign-key-error",
          "name": "ForeignKey Error",
          "tags": [
            "#table",
            "#row"
          ],
          "note": "for \"id_desdobramento_3\": values \"4026\" not found in the lookup table \"dm_desdobramento_3_rec\" as \"id_desdobramento_3\"",
          "message": "Row at position \"20365\" violates the foreign key: for \"id_desdobramento_3\": values \"4026\" not found in the lookup table \"dm_desdobramento_3_rec\" as \"id_desdobramento_3\"",
          "description": "Values in the foreign key fields should exist in the reference table"
        },
        {
          "cells": [
            "1000",
            "4271",
            "16",
            "146",
            "153",
            "2120",
            "4026",
            "7443",
            "15716",
            "16461",
            "96",
            "70",
            "2448019118001",
            "2022",
            "6152446.00"
          ],
          "rowNumber": 20364,
          "rowPosition": 20365,
          "code": "foreign-key-error",
          "name": "ForeignKey Error",
          "tags": [
            "#table",
            "#row"
          ],
          "note": "for \"id_desdobramento_2\": values \"2120\" not found in the lookup table \"dm_desdobramento_2_rec\" as \"id_desdobramento_2\"",
          "message": "Row at position \"20365\" violates the foreign key: for \"id_desdobramento_2\": values \"2120\" not found in the lookup table \"dm_desdobramento_2_rec\" as \"id_desdobramento_2\"",
          "description": "Values in the foreign key fields should exist in the reference table"
        },
        {
          "cells": [
            "1001",
            "4271",
            "16",
            "146",
            "153",
            "2120",
            "4026",
            "7443",
            "15716",
            "16461",
            "96",
            "70",
            "2448019118001",
            "2022",
            "994050.00"
          ],
          "rowNumber": 20365,
          "rowPosition": 20366,
          "code": "foreign-key-error",
          "name": "ForeignKey Error",
          "tags": [
            "#table",
            "#row"
          ],
          "note": "for \"id_desdobramento_3\": values \"4026\" not found in the lookup table \"dm_desdobramento_3_rec\" as \"id_desdobramento_3\"",
          "message": "Row at position \"20366\" violates the foreign key: for \"id_desdobramento_3\": values \"4026\" not found in the lookup table \"dm_desdobramento_3_rec\" as \"id_desdobramento_3\"",
          "description": "Values in the foreign key fields should exist in the reference table"
        },
        {
          "cells": [
            "1001",
            "4271",
            "16",
            "146",
            "153",
            "2120",
            "4026",
            "7443",
            "15716",
            "16461",
            "96",
            "70",
            "2448019118001",
            "2022",
            "994050.00"
          ],
          "rowNumber": 20365,
          "rowPosition": 20366,
          "code": "foreign-key-error",
          "name": "ForeignKey Error",
          "tags": [
            "#table",
            "#row"
          ],
          "note": "for \"id_desdobramento_2\": values \"2120\" not found in the lookup table \"dm_desdobramento_2_rec\" as \"id_desdobramento_2\"",
          "message": "Row at position \"20366\" violates the foreign key: for \"id_desdobramento_2\": values \"2120\" not found in the lookup table \"dm_desdobramento_2_rec\" as \"id_desdobramento_2\"",
          "description": "Values in the foreign key fields should exist in the reference table"
        },
        {
          "cells": [
            "999",
            "4224",
            "540",
            "798",
            "969",
            "2124",
            "4052",
            "7467",
            "15941",
            "16785",
            "54",
            "20",
            "9118012102000",
            "2022",
            "-286831216.22"
          ],
          "rowNumber": 20380,
          "rowPosition": 20381,
          "code": "foreign-key-error",
          "name": "ForeignKey Error",
          "tags": [
            "#table",
            "#row"
          ],
          "note": "for \"id_desdobramento_3\": values \"4052\" not found in the lookup table \"dm_desdobramento_3_rec\" as \"id_desdobramento_3\"",
          "message": "Row at position \"20381\" violates the foreign key: for \"id_desdobramento_3\": values \"4052\" not found in the lookup table \"dm_desdobramento_3_rec\" as \"id_desdobramento_3\"",
          "description": "Values in the foreign key fields should exist in the reference table"
        },
        {
          "cells": [
            "999",
            "4224",
            "540",
            "798",
            "969",
            "2124",
            "4052",
            "7467",
            "15941",
            "16785",
            "54",
            "20",
            "9118012102000",
            "2022",
            "-286831216.22"
          ],
          "rowNumber": 20380,
          "rowPosition": 20381,
          "code": "foreign-key-error",
          "name": "ForeignKey Error",
          "tags": [
            "#table",
            "#row"
          ],
          "note": "for \"id_desdobramento_2\": values \"2124\" not found in the lookup table \"dm_desdobramento_2_rec\" as \"id_desdobramento_2\"",
          "message": "Row at position \"20381\" violates the foreign key: for \"id_desdobramento_2\": values \"2124\" not found in the lookup table \"dm_desdobramento_2_rec\" as \"id_desdobramento_2\"",
          "description": "Values in the foreign key fields should exist in the reference table"
        },
        {
          "cells": [
            "1001",
            "4224",
            "541",
            "799",
            "971",
            "2125",
            "4048",
            "7468",
            "15939",
            "16782",
            "54",
            "20",
            "9118012302000",
            "2022",
            "-4243605.02"
          ],
          "rowNumber": 20381,
          "rowPosition": 20382,
          "code": "foreign-key-error",
          "name": "ForeignKey Error",
          "tags": [
            "#table",
            "#row"
          ],
          "note": "for \"id_desdobramento_3\": values \"4048\" not found in the lookup table \"dm_desdobramento_3_rec\" as \"id_desdobramento_3\"",
          "message": "Row at position \"20382\" violates the foreign key: for \"id_desdobramento_3\": values \"4048\" not found in the lookup table \"dm_desdobramento_3_rec\" as \"id_desdobramento_3\"",
          "description": "Values in the foreign key fields should exist in the reference table"
        },
        {
          "cells": [
            "1001",
            "4224",
            "541",
            "799",
            "971",
            "2125",
            "4048",
            "7468",
            "15939",
            "16782",
            "54",
            "20",
            "9118012302000",
            "2022",
            "-4243605.02"
          ],
          "rowNumber": 20381,
          "rowPosition": 20382,
          "code": "foreign-key-error",
          "name": "ForeignKey Error",
          "tags": [
            "#table",
            "#row"
          ],
          "note": "for \"id_desdobramento_2\": values \"2125\" not found in the lookup table \"dm_desdobramento_2_rec\" as \"id_desdobramento_2\"",
          "message": "Row at position \"20382\" violates the foreign key: for \"id_desdobramento_2\": values \"2125\" not found in the lookup table \"dm_desdobramento_2_rec\" as \"id_desdobramento_2\"",
          "description": "Values in the foreign key fields should exist in the reference table"
        },
        {
          "cells": [
            "1001",
            "4247",
            "531",
            "792",
            "966",
            "2118",
            "4036",
            "7447",
            "15648",
            "16364",
            "4",
            "23",
            "9118022202000",
            "2022",
            "0.00"
          ],
          "rowNumber": 20384,
          "rowPosition": 20385,
          "code": "foreign-key-error",
          "name": "ForeignKey Error",
          "tags": [
            "#table",
            "#row"
          ],
          "note": "for \"id_desdobramento_3\": values \"4036\" not found in the lookup table \"dm_desdobramento_3_rec\" as \"id_desdobramento_3\"",
          "message": "Row at position \"20385\" violates the foreign key: for \"id_desdobramento_3\": values \"4036\" not found in the lookup table \"dm_desdobramento_3_rec\" as \"id_desdobramento_3\"",
          "description": "Values in the foreign key fields should exist in the reference table"
        },
        {
          "cells": [
            "1001",
            "4247",
            "531",
            "792",
            "966",
            "2118",
            "4036",
            "7447",
            "15648",
            "16364",
            "4",
            "23",
            "9118022202000",
            "2022",
            "0.00"
          ],
          "rowNumber": 20384,
          "rowPosition": 20385,
          "code": "foreign-key-error",
          "name": "ForeignKey Error",
          "tags": [
            "#table",
            "#row"
          ],
          "note": "for \"id_desdobramento_2\": values \"2118\" not found in the lookup table \"dm_desdobramento_2_rec\" as \"id_desdobramento_2\"",
          "message": "Row at position \"20385\" violates the foreign key: for \"id_desdobramento_2\": values \"2118\" not found in the lookup table \"dm_desdobramento_2_rec\" as \"id_desdobramento_2\"",
          "description": "Values in the foreign key fields should exist in the reference table"
        },
        {
          "cells": [
            "1000",
            "4224",
            "535",
            "793",
            "964",
            "2121",
            "4045",
            "7453",
            "15654",
            "16366",
            "4",
            "23",
            "9118022302000",
            "2022",
            "-15911.13"
          ],
          "rowNumber": 20385,
          "rowPosition": 20386,
          "code": "foreign-key-error",
          "name": "ForeignKey Error",
          "tags": [
            "#table",
            "#row"
          ],
          "note": "for \"id_desdobramento_3\": values \"4045\" not found in the lookup table \"dm_desdobramento_3_rec\" as \"id_desdobramento_3\"",
          "message": "Row at position \"20386\" violates the foreign key: for \"id_desdobramento_3\": values \"4045\" not found in the lookup table \"dm_desdobramento_3_rec\" as \"id_desdobramento_3\"",
          "description": "Values in the foreign key fields should exist in the reference table"
        },
        {
          "cells": [
            "1000",
            "4224",
            "535",
            "793",
            "964",
            "2121",
            "4045",
            "7453",
            "15654",
            "16366",
            "4",
            "23",
            "9118022302000",
            "2022",
            "-15911.13"
          ],
          "rowNumber": 20385,
          "rowPosition": 20386,
          "code": "foreign-key-error",
          "name": "ForeignKey Error",
          "tags": [
            "#table",
            "#row"
          ],
          "note": "for \"id_desdobramento_2\": values \"2121\" not found in the lookup table \"dm_desdobramento_2_rec\" as \"id_desdobramento_2\"",
          "message": "Row at position \"20386\" violates the foreign key: for \"id_desdobramento_2\": values \"2121\" not found in the lookup table \"dm_desdobramento_2_rec\" as \"id_desdobramento_2\"",
          "description": "Values in the foreign key fields should exist in the reference table"
        },
        {
          "cells": [
            "999",
            "4224",
            "530",
            "794",
            "965",
            "2119",
            "4042",
            "7460",
            "15651",
            "16365",
            "4",
            "23",
            "9118022102000",
            "2022",
            "-14333410.63"
          ],
          "rowNumber": 20409,
          "rowPosition": 20410,
          "code": "foreign-key-error",
          "name": "ForeignKey Error",
          "tags": [
            "#table",
            "#row"
          ],
          "note": "for \"id_desdobramento_3\": values \"4042\" not found in the lookup table \"dm_desdobramento_3_rec\" as \"id_desdobramento_3\"",
          "message": "Row at position \"20410\" violates the foreign key: for \"id_desdobramento_3\": values \"4042\" not found in the lookup table \"dm_desdobramento_3_rec\" as \"id_desdobramento_3\"",
          "description": "Values in the foreign key fields should exist in the reference table"
        },
        {
          "cells": [
            "999",
            "4224",
            "530",
            "794",
            "965",
            "2119",
            "4042",
            "7460",
            "15651",
            "16365",
            "4",
            "23",
            "9118022102000",
            "2022",
            "-14333410.63"
          ],
          "rowNumber": 20409,
          "rowPosition": 20410,
          "code": "foreign-key-error",
          "name": "ForeignKey Error",
          "tags": [
            "#table",
            "#row"
          ],
          "note": "for \"id_desdobramento_2\": values \"2119\" not found in the lookup table \"dm_desdobramento_2_rec\" as \"id_desdobramento_2\"",
          "message": "Row at position \"20410\" violates the foreign key: for \"id_desdobramento_2\": values \"2119\" not found in the lookup table \"dm_desdobramento_2_rec\" as \"id_desdobramento_2\"",
          "description": "Values in the foreign key fields should exist in the reference table"
        },
        {
          "cells": [
            "995",
            "4144",
            "528",
            "50",
            "963",
            "2112",
            "4025",
            "7432",
            "15651",
            "16365",
            "4",
            "23",
            "9118022102000",
            "2021",
            "-18200698.72"
          ],
          "rowNumber": 20417,
          "rowPosition": 20418,
          "code": "foreign-key-error",
          "name": "ForeignKey Error",
          "tags": [
            "#table",
            "#row"
          ],
          "note": "for \"id_desdobramento_3\": values \"4025\" not found in the lookup table \"dm_desdobramento_3_rec\" as \"id_desdobramento_3\"",
          "message": "Row at position \"20418\" violates the foreign key: for \"id_desdobramento_3\": values \"4025\" not found in the lookup table \"dm_desdobramento_3_rec\" as \"id_desdobramento_3\"",
          "description": "Values in the foreign key fields should exist in the reference table"
        },
        {
          "cells": [
            "995",
            "4144",
            "528",
            "50",
            "963",
            "2112",
            "4025",
            "7432",
            "15651",
            "16365",
            "4",
            "23",
            "9118022102000",
            "2021",
            "-18200698.72"
          ],
          "rowNumber": 20417,
          "rowPosition": 20418,
          "code": "foreign-key-error",
          "name": "ForeignKey Error",
          "tags": [
            "#table",
            "#row"
          ],
          "note": "for \"id_desdobramento_2\": values \"2112\" not found in the lookup table \"dm_desdobramento_2_rec\" as \"id_desdobramento_2\"",
          "message": "Row at position \"20418\" violates the foreign key: for \"id_desdobramento_2\": values \"2112\" not found in the lookup table \"dm_desdobramento_2_rec\" as \"id_desdobramento_2\"",
          "description": "Values in the foreign key fields should exist in the reference table"
        },
        {
          "cells": [
            "978",
            "4032",
            "10",
            "145",
            "173",
            "437",
            "4020",
            "7427",
            "15615",
            "16001",
            "355",
            "92",
            "1718039101000",
            "2020",
            "1899868.00"
          ],
          "rowNumber": 20659,
          "rowPosition": 20660,
          "code": "foreign-key-error",
          "name": "ForeignKey Error",
          "tags": [
            "#table",
            "#row"
          ],
          "note": "for \"id_desdobramento_3\": values \"4020\" not found in the lookup table \"dm_desdobramento_3_rec\" as \"id_desdobramento_3\"",
          "message": "Row at position \"20660\" violates the foreign key: for \"id_desdobramento_3\": values \"4020\" not found in the lookup table \"dm_desdobramento_3_rec\" as \"id_desdobramento_3\"",
          "description": "Values in the foreign key fields should exist in the reference table"
        },
        {
          "cells": [
            "978",
            "4016",
            "527",
            "75",
            "962",
            "68",
            "4021",
            "7428",
            "15618",
            "16014",
            "25",
            "60",
            "9321001101000",
            "2020",
            "-61603.17"
          ],
          "rowNumber": 20660,
          "rowPosition": 20661,
          "code": "foreign-key-error",
          "name": "ForeignKey Error",
          "tags": [
            "#table",
            "#row"
          ],
          "note": "for \"id_desdobramento_3\": values \"4021\" not found in the lookup table \"dm_desdobramento_3_rec\" as \"id_desdobramento_3\"",
          "message": "Row at position \"20661\" violates the foreign key: for \"id_desdobramento_3\": values \"4021\" not found in the lookup table \"dm_desdobramento_3_rec\" as \"id_desdobramento_3\"",
          "description": "Values in the foreign key fields should exist in the reference table"
        },
        {
          "cells": [
            "986",
            "4113",
            "10",
            "145",
            "173",
            "437",
            "4020",
            "7427",
            "15615",
            "16001",
            "355",
            "92",
            "1718039101000",
            "2021",
            "12105263.85"
          ],
          "rowNumber": 21348,
          "rowPosition": 21349,
          "code": "foreign-key-error",
          "name": "ForeignKey Error",
          "tags": [
            "#table",
            "#row"
          ],
          "note": "for \"id_desdobramento_3\": values \"4020\" not found in the lookup table \"dm_desdobramento_3_rec\" as \"id_desdobramento_3\"",
          "message": "Row at position \"21349\" violates the foreign key: for \"id_desdobramento_3\": values \"4020\" not found in the lookup table \"dm_desdobramento_3_rec\" as \"id_desdobramento_3\"",
          "description": "Values in the foreign key fields should exist in the reference table"
        },
        {
          "cells": [
            "984",
            "4113",
            "10",
            "145",
            "173",
            "437",
            "4020",
            "7427",
            "15615",
            "16001",
            "355",
            "92",
            "1718039101000",
            "2021",
            "52438770.93"
          ],
          "rowNumber": 21349,
          "rowPosition": 21350,
          "code": "foreign-key-error",
          "name": "ForeignKey Error",
          "tags": [
            "#table",
            "#row"
          ],
          "note": "for \"id_desdobramento_3\": values \"4020\" not found in the lookup table \"dm_desdobramento_3_rec\" as \"id_desdobramento_3\"",
          "message": "Row at position \"21350\" violates the foreign key: for \"id_desdobramento_3\": values \"4020\" not found in the lookup table \"dm_desdobramento_3_rec\" as \"id_desdobramento_3\"",
          "description": "Values in the foreign key fields should exist in the reference table"
        },
        {
          "cells": [
            "980",
            "4032",
            "16",
            "145",
            "173",
            "199",
            "4020",
            "7427",
            "15616",
            "15997",
            "356",
            "93",
            "2418039101000",
            "2020",
            "4432450.00"
          ],
          "rowNumber": 22030,
          "rowPosition": 22031,
          "code": "foreign-key-error",
          "name": "ForeignKey Error",
          "tags": [
            "#table",
            "#row"
          ],
          "note": "for \"id_desdobramento_3\": values \"4020\" not found in the lookup table \"dm_desdobramento_3_rec\" as \"id_desdobramento_3\"",
          "message": "Row at position \"22031\" violates the foreign key: for \"id_desdobramento_3\": values \"4020\" not found in the lookup table \"dm_desdobramento_3_rec\" as \"id_desdobramento_3\"",
          "description": "Values in the foreign key fields should exist in the reference table"
        },
        {
          "cells": [
            "999",
            "4224",
            "542",
            "800",
            "967",
            "2127",
            "4050",
            "7465",
            "15940",
            "16781",
            "54",
            "20",
            "9118012202000",
            "2022",
            "-11082756.57"
          ],
          "rowNumber": 22169,
          "rowPosition": 22170,
          "code": "foreign-key-error",
          "name": "ForeignKey Error",
          "tags": [
            "#table",
            "#row"
          ],
          "note": "for \"id_desdobramento_3\": values \"4050\" not found in the lookup table \"dm_desdobramento_3_rec\" as \"id_desdobramento_3\"",
          "message": "Row at position \"22170\" violates the foreign key: for \"id_desdobramento_3\": values \"4050\" not found in the lookup table \"dm_desdobramento_3_rec\" as \"id_desdobramento_3\"",
          "description": "Values in the foreign key fields should exist in the reference table"
        },
        {
          "cells": [
            "999",
            "4224",
            "542",
            "800",
            "967",
            "2127",
            "4050",
            "7465",
            "15940",
            "16781",
            "54",
            "20",
            "9118012202000",
            "2022",
            "-11082756.57"
          ],
          "rowNumber": 22169,
          "rowPosition": 22170,
          "code": "foreign-key-error",
          "name": "ForeignKey Error",
          "tags": [
            "#table",
            "#row"
          ],
          "note": "for \"id_desdobramento_2\": values \"2127\" not found in the lookup table \"dm_desdobramento_2_rec\" as \"id_desdobramento_2\"",
          "message": "Row at position \"22170\" violates the foreign key: for \"id_desdobramento_2\": values \"2127\" not found in the lookup table \"dm_desdobramento_2_rec\" as \"id_desdobramento_2\"",
          "description": "Values in the foreign key fields should exist in the reference table"
        },
        {
          "cells": [
            "1001",
            "4247",
            "530",
            "794",
            "965",
            "2119",
            "4042",
            "7460",
            "15651",
            "16365",
            "4",
            "23",
            "9118022102000",
            "2022",
            "0.00"
          ],
          "rowNumber": 22173,
          "rowPosition": 22174,
          "code": "foreign-key-error",
          "name": "ForeignKey Error",
          "tags": [
            "#table",
            "#row"
          ],
          "note": "for \"id_desdobramento_3\": values \"4042\" not found in the lookup table \"dm_desdobramento_3_rec\" as \"id_desdobramento_3\"",
          "message": "Row at position \"22174\" violates the foreign key: for \"id_desdobramento_3\": values \"4042\" not found in the lookup table \"dm_desdobramento_3_rec\" as \"id_desdobramento_3\"",
          "description": "Values in the foreign key fields should exist in the reference table"
        },
        {
          "cells": [
            "1001",
            "4247",
            "530",
            "794",
            "965",
            "2119",
            "4042",
            "7460",
            "15651",
            "16365",
            "4",
            "23",
            "9118022102000",
            "2022",
            "0.00"
          ],
          "rowNumber": 22173,
          "rowPosition": 22174,
          "code": "foreign-key-error",
          "name": "ForeignKey Error",
          "tags": [
            "#table",
            "#row"
          ],
          "note": "for \"id_desdobramento_2\": values \"2119\" not found in the lookup table \"dm_desdobramento_2_rec\" as \"id_desdobramento_2\"",
          "message": "Row at position \"22174\" violates the foreign key: for \"id_desdobramento_2\": values \"2119\" not found in the lookup table \"dm_desdobramento_2_rec\" as \"id_desdobramento_2\"",
          "description": "Values in the foreign key fields should exist in the reference table"
        },
        {
          "cells": [
            "999",
            "4224",
            "535",
            "793",
            "964",
            "2121",
            "4045",
            "7453",
            "15654",
            "16366",
            "4",
            "23",
            "9118022302000",
            "2022",
            "-14330.01"
          ],
          "rowNumber": 22174,
          "rowPosition": 22175,
          "code": "foreign-key-error",
          "name": "ForeignKey Error",
          "tags": [
            "#table",
            "#row"
          ],
          "note": "for \"id_desdobramento_3\": values \"4045\" not found in the lookup table \"dm_desdobramento_3_rec\" as \"id_desdobramento_3\"",
          "message": "Row at position \"22175\" violates the foreign key: for \"id_desdobramento_3\": values \"4045\" not found in the lookup table \"dm_desdobramento_3_rec\" as \"id_desdobramento_3\"",
          "description": "Values in the foreign key fields should exist in the reference table"
        },
        {
          "cells": [
            "999",
            "4224",
            "535",
            "793",
            "964",
            "2121",
            "4045",
            "7453",
            "15654",
            "16366",
            "4",
            "23",
            "9118022302000",
            "2022",
            "-14330.01"
          ],
          "rowNumber": 22174,
          "rowPosition": 22175,
          "code": "foreign-key-error",
          "name": "ForeignKey Error",
          "tags": [
            "#table",
            "#row"
          ],
          "note": "for \"id_desdobramento_2\": values \"2121\" not found in the lookup table \"dm_desdobramento_2_rec\" as \"id_desdobramento_2\"",
          "message": "Row at position \"22175\" violates the foreign key: for \"id_desdobramento_2\": values \"2121\" not found in the lookup table \"dm_desdobramento_2_rec\" as \"id_desdobramento_2\"",
          "description": "Values in the foreign key fields should exist in the reference table"
        },
        {
          "cells": [
            "992",
            "4144",
            "528",
            "50",
            "963",
            "2112",
            "4025",
            "7432",
            "15651",
            "16365",
            "4",
            "23",
            "9118022102000",
            "2021",
            "-12737167.16"
          ],
          "rowNumber": 22178,
          "rowPosition": 22179,
          "code": "foreign-key-error",
          "name": "ForeignKey Error",
          "tags": [
            "#table",
            "#row"
          ],
          "note": "for \"id_desdobramento_3\": values \"4025\" not found in the lookup table \"dm_desdobramento_3_rec\" as \"id_desdobramento_3\"",
          "message": "Row at position \"22179\" violates the foreign key: for \"id_desdobramento_3\": values \"4025\" not found in the lookup table \"dm_desdobramento_3_rec\" as \"id_desdobramento_3\"",
          "description": "Values in the foreign key fields should exist in the reference table"
        },
        {
          "cells": [
            "992",
            "4144",
            "528",
            "50",
            "963",
            "2112",
            "4025",
            "7432",
            "15651",
            "16365",
            "4",
            "23",
            "9118022102000",
            "2021",
            "-12737167.16"
          ],
          "rowNumber": 22178,
          "rowPosition": 22179,
          "code": "foreign-key-error",
          "name": "ForeignKey Error",
          "tags": [
            "#table",
            "#row"
          ],
          "note": "for \"id_desdobramento_2\": values \"2112\" not found in the lookup table \"dm_desdobramento_2_rec\" as \"id_desdobramento_2\"",
          "message": "Row at position \"22179\" violates the foreign key: for \"id_desdobramento_2\": values \"2112\" not found in the lookup table \"dm_desdobramento_2_rec\" as \"id_desdobramento_2\"",
          "description": "Values in the foreign key fields should exist in the reference table"
        },
        {
          "cells": [
            "993",
            "4144",
            "528",
            "50",
            "963",
            "2112",
            "4025",
            "7430",
            "15648",
            "16364",
            "4",
            "23",
            "9118022202000",
            "2021",
            "-28423.82"
          ],
          "rowNumber": 22180,
          "rowPosition": 22181,
          "code": "foreign-key-error",
          "name": "ForeignKey Error",
          "tags": [
            "#table",
            "#row"
          ],
          "note": "for \"id_desdobramento_3\": values \"4025\" not found in the lookup table \"dm_desdobramento_3_rec\" as \"id_desdobramento_3\"",
          "message": "Row at position \"22181\" violates the foreign key: for \"id_desdobramento_3\": values \"4025\" not found in the lookup table \"dm_desdobramento_3_rec\" as \"id_desdobramento_3\"",
          "description": "Values in the foreign key fields should exist in the reference table"
        },
        {
          "cells": [
            "993",
            "4144",
            "528",
            "50",
            "963",
            "2112",
            "4025",
            "7430",
            "15648",
            "16364",
            "4",
            "23",
            "9118022202000",
            "2021",
            "-28423.82"
          ],
          "rowNumber": 22180,
          "rowPosition": 22181,
          "code": "foreign-key-error",
          "name": "ForeignKey Error",
          "tags": [
            "#table",
            "#row"
          ],
          "note": "for \"id_desdobramento_2\": values \"2112\" not found in the lookup table \"dm_desdobramento_2_rec\" as \"id_desdobramento_2\"",
          "message": "Row at position \"22181\" violates the foreign key: for \"id_desdobramento_2\": values \"2112\" not found in the lookup table \"dm_desdobramento_2_rec\" as \"id_desdobramento_2\"",
          "description": "Values in the foreign key fields should exist in the reference table"
        },
        {
          "cells": [
            "1002",
            "4224",
            "539",
            "795",
            "973",
            "2122",
            "4053",
            "7464",
            "15942",
            "16788",
            "89",
            "51",
            "9718017101002",
            "2022",
            "-6513303.35"
          ],
          "rowNumber": 22318,
          "rowPosition": 22319,
          "code": "foreign-key-error",
          "name": "ForeignKey Error",
          "tags": [
            "#table",
            "#row"
          ],
          "note": "for \"id_desdobramento_3\": values \"4053\" not found in the lookup table \"dm_desdobramento_3_rec\" as \"id_desdobramento_3\"",
          "message": "Row at position \"22319\" violates the foreign key: for \"id_desdobramento_3\": values \"4053\" not found in the lookup table \"dm_desdobramento_3_rec\" as \"id_desdobramento_3\"",
          "description": "Values in the foreign key fields should exist in the reference table"
        },
        {
          "cells": [
            "1002",
            "4224",
            "539",
            "795",
            "973",
            "2122",
            "4053",
            "7464",
            "15942",
            "16788",
            "89",
            "51",
            "9718017101002",
            "2022",
            "-6513303.35"
          ],
          "rowNumber": 22318,
          "rowPosition": 22319,
          "code": "foreign-key-error",
          "name": "ForeignKey Error",
          "tags": [
            "#table",
            "#row"
          ],
          "note": "for \"id_desdobramento_2\": values \"2122\" not found in the lookup table \"dm_desdobramento_2_rec\" as \"id_desdobramento_2\"",
          "message": "Row at position \"22319\" violates the foreign key: for \"id_desdobramento_2\": values \"2122\" not found in the lookup table \"dm_desdobramento_2_rec\" as \"id_desdobramento_2\"",
          "description": "Values in the foreign key fields should exist in the reference table"
        },
        {
          "cells": [
            "1000",
            "4247",
            "535",
            "793",
            "964",
            "2121",
            "4045",
            "7453",
            "15654",
            "16366",
            "4",
            "23",
            "9118022302000",
            "2022",
            "0.00"
          ],
          "rowNumber": 22319,
          "rowPosition": 22320,
          "code": "foreign-key-error",
          "name": "ForeignKey Error",
          "tags": [
            "#table",
            "#row"
          ],
          "note": "for \"id_desdobramento_3\": values \"4045\" not found in the lookup table \"dm_desdobramento_3_rec\" as \"id_desdobramento_3\"",
          "message": "Row at position \"22320\" violates the foreign key: for \"id_desdobramento_3\": values \"4045\" not found in the lookup table \"dm_desdobramento_3_rec\" as \"id_desdobramento_3\"",
          "description": "Values in the foreign key fields should exist in the reference table"
        },
        {
          "cells": [
            "1000",
            "4247",
            "535",
            "793",
            "964",
            "2121",
            "4045",
            "7453",
            "15654",
            "16366",
            "4",
            "23",
            "9118022302000",
            "2022",
            "0.00"
          ],
          "rowNumber": 22319,
          "rowPosition": 22320,
          "code": "foreign-key-error",
          "name": "ForeignKey Error",
          "tags": [
            "#table",
            "#row"
          ],
          "note": "for \"id_desdobramento_2\": values \"2121\" not found in the lookup table \"dm_desdobramento_2_rec\" as \"id_desdobramento_2\"",
          "message": "Row at position \"22320\" violates the foreign key: for \"id_desdobramento_2\": values \"2121\" not found in the lookup table \"dm_desdobramento_2_rec\" as \"id_desdobramento_2\"",
          "description": "Values in the foreign key fields should exist in the reference table"
        },
        {
          "cells": [
            "1002",
            "4224",
            "542",
            "800",
            "967",
            "2127",
            "4050",
            "7465",
            "15940",
            "16781",
            "54",
            "20",
            "9118012202000",
            "2022",
            "-5769274.01"
          ],
          "rowNumber": 22845,
          "rowPosition": 22846,
          "code": "foreign-key-error",
          "name": "ForeignKey Error",
          "tags": [
            "#table",
            "#row"
          ],
          "note": "for \"id_desdobramento_3\": values \"4050\" not found in the lookup table \"dm_desdobramento_3_rec\" as \"id_desdobramento_3\"",
          "message": "Row at position \"22846\" violates the foreign key: for \"id_desdobramento_3\": values \"4050\" not found in the lookup table \"dm_desdobramento_3_rec\" as \"id_desdobramento_3\"",
          "description": "Values in the foreign key fields should exist in the reference table"
        },
        {
          "cells": [
            "1002",
            "4224",
            "542",
            "800",
            "967",
            "2127",
            "4050",
            "7465",
            "15940",
            "16781",
            "54",
            "20",
            "9118012202000",
            "2022",
            "-5769274.01"
          ],
          "rowNumber": 22845,
          "rowPosition": 22846,
          "code": "foreign-key-error",
          "name": "ForeignKey Error",
          "tags": [
            "#table",
            "#row"
          ],
          "note": "for \"id_desdobramento_2\": values \"2127\" not found in the lookup table \"dm_desdobramento_2_rec\" as \"id_desdobramento_2\"",
          "message": "Row at position \"22846\" violates the foreign key: for \"id_desdobramento_2\": values \"2127\" not found in the lookup table \"dm_desdobramento_2_rec\" as \"id_desdobramento_2\"",
          "description": "Values in the foreign key fields should exist in the reference table"
        },
        {
          "cells": [
            "1002",
            "4224",
            "541",
            "799",
            "971",
            "2125",
            "4048",
            "7468",
            "15939",
            "16782",
            "54",
            "20",
            "9118012302000",
            "2022",
            "-1489425.44"
          ],
          "rowNumber": 22846,
          "rowPosition": 22847,
          "code": "foreign-key-error",
          "name": "ForeignKey Error",
          "tags": [
            "#table",
            "#row"
          ],
          "note": "for \"id_desdobramento_3\": values \"4048\" not found in the lookup table \"dm_desdobramento_3_rec\" as \"id_desdobramento_3\"",
          "message": "Row at position \"22847\" violates the foreign key: for \"id_desdobramento_3\": values \"4048\" not found in the lookup table \"dm_desdobramento_3_rec\" as \"id_desdobramento_3\"",
          "description": "Values in the foreign key fields should exist in the reference table"
        },
        {
          "cells": [
            "1002",
            "4224",
            "541",
            "799",
            "971",
            "2125",
            "4048",
            "7468",
            "15939",
            "16782",
            "54",
            "20",
            "9118012302000",
            "2022",
            "-1489425.44"
          ],
          "rowNumber": 22846,
          "rowPosition": 22847,
          "code": "foreign-key-error",
          "name": "ForeignKey Error",
          "tags": [
            "#table",
            "#row"
          ],
          "note": "for \"id_desdobramento_2\": values \"2125\" not found in the lookup table \"dm_desdobramento_2_rec\" as \"id_desdobramento_2\"",
          "message": "Row at position \"22847\" violates the foreign key: for \"id_desdobramento_2\": values \"2125\" not found in the lookup table \"dm_desdobramento_2_rec\" as \"id_desdobramento_2\"",
          "description": "Values in the foreign key fields should exist in the reference table"
        },
        {
          "cells": [
            "1002",
            "4224",
            "531",
            "792",
            "966",
            "2118",
            "4036",
            "7447",
            "15648",
            "16364",
            "4",
            "23",
            "9118022202000",
            "2022",
            "-10412.05"
          ],
          "rowNumber": 23508,
          "rowPosition": 23509,
          "code": "foreign-key-error",
          "name": "ForeignKey Error",
          "tags": [
            "#table",
            "#row"
          ],
          "note": "for \"id_desdobramento_3\": values \"4036\" not found in the lookup table \"dm_desdobramento_3_rec\" as \"id_desdobramento_3\"",
          "message": "Row at position \"23509\" violates the foreign key: for \"id_desdobramento_3\": values \"4036\" not found in the lookup table \"dm_desdobramento_3_rec\" as \"id_desdobramento_3\"",
          "description": "Values in the foreign key fields should exist in the reference table"
        },
        {
          "cells": [
            "1002",
            "4224",
            "531",
            "792",
            "966",
            "2118",
            "4036",
            "7447",
            "15648",
            "16364",
            "4",
            "23",
            "9118022202000",
            "2022",
            "-10412.05"
          ],
          "rowNumber": 23508,
          "rowPosition": 23509,
          "code": "foreign-key-error",
          "name": "ForeignKey Error",
          "tags": [
            "#table",
            "#row"
          ],
          "note": "for \"id_desdobramento_2\": values \"2118\" not found in the lookup table \"dm_desdobramento_2_rec\" as \"id_desdobramento_2\"",
          "message": "Row at position \"23509\" violates the foreign key: for \"id_desdobramento_2\": values \"2118\" not found in the lookup table \"dm_desdobramento_2_rec\" as \"id_desdobramento_2\"",
          "description": "Values in the foreign key fields should exist in the reference table"
        },
        {
          "cells": [
            "994",
            "4144",
            "528",
            "50",
            "963",
            "2112",
            "4025",
            "7433",
            "15654",
            "16366",
            "4",
            "23",
            "9118022302000",
            "2021",
            "-10265.54"
          ],
          "rowNumber": 23513,
          "rowPosition": 23514,
          "code": "foreign-key-error",
          "name": "ForeignKey Error",
          "tags": [
            "#table",
            "#row"
          ],
          "note": "for \"id_desdobramento_3\": values \"4025\" not found in the lookup table \"dm_desdobramento_3_rec\" as \"id_desdobramento_3\"",
          "message": "Row at position \"23514\" violates the foreign key: for \"id_desdobramento_3\": values \"4025\" not found in the lookup table \"dm_desdobramento_3_rec\" as \"id_desdobramento_3\"",
          "description": "Values in the foreign key fields should exist in the reference table"
        },
        {
          "cells": [
            "994",
            "4144",
            "528",
            "50",
            "963",
            "2112",
            "4025",
            "7433",
            "15654",
            "16366",
            "4",
            "23",
            "9118022302000",
            "2021",
            "-10265.54"
          ],
          "rowNumber": 23513,
          "rowPosition": 23514,
          "code": "foreign-key-error",
          "name": "ForeignKey Error",
          "tags": [
            "#table",
            "#row"
          ],
          "note": "for \"id_desdobramento_2\": values \"2112\" not found in the lookup table \"dm_desdobramento_2_rec\" as \"id_desdobramento_2\"",
          "message": "Row at position \"23514\" violates the foreign key: for \"id_desdobramento_2\": values \"2112\" not found in the lookup table \"dm_desdobramento_2_rec\" as \"id_desdobramento_2\"",
          "description": "Values in the foreign key fields should exist in the reference table"
        },
        {
          "cells": [
            "2265",
            "4032",
            "10",
            "145",
            "173",
            "437",
            "4020",
            "7427",
            "15615",
            "16001",
            "355",
            "92",
            "1718039101000",
            "2020",
            "0.00"
          ],
          "rowNumber": 23878,
          "rowPosition": 23879,
          "code": "foreign-key-error",
          "name": "ForeignKey Error",
          "tags": [
            "#table",
            "#row"
          ],
          "note": "for \"id_desdobramento_3\": values \"4020\" not found in the lookup table \"dm_desdobramento_3_rec\" as \"id_desdobramento_3\"",
          "message": "Row at position \"23879\" violates the foreign key: for \"id_desdobramento_3\": values \"4020\" not found in the lookup table \"dm_desdobramento_3_rec\" as \"id_desdobramento_3\"",
          "description": "Values in the foreign key fields should exist in the reference table"
        },
        {
          "cells": [
            "991",
            "4144",
            "528",
            "50",
            "963",
            "2112",
            "4025",
            "7432",
            "15651",
            "16365",
            "4",
            "23",
            "9118022102000",
            "2021",
            "-12628409.00"
          ],
          "rowNumber": 24958,
          "rowPosition": 24959,
          "code": "foreign-key-error",
          "name": "ForeignKey Error",
          "tags": [
            "#table",
            "#row"
          ],
          "note": "for \"id_desdobramento_3\": values \"4025\" not found in the lookup table \"dm_desdobramento_3_rec\" as \"id_desdobramento_3\"",
          "message": "Row at position \"24959\" violates the foreign key: for \"id_desdobramento_3\": values \"4025\" not found in the lookup table \"dm_desdobramento_3_rec\" as \"id_desdobramento_3\"",
          "description": "Values in the foreign key fields should exist in the reference table"
        },
        {
          "cells": [
            "991",
            "4144",
            "528",
            "50",
            "963",
            "2112",
            "4025",
            "7432",
            "15651",
            "16365",
            "4",
            "23",
            "9118022102000",
            "2021",
            "-12628409.00"
          ],
          "rowNumber": 24958,
          "rowPosition": 24959,
          "code": "foreign-key-error",
          "name": "ForeignKey Error",
          "tags": [
            "#table",
            "#row"
          ],
          "note": "for \"id_desdobramento_2\": values \"2112\" not found in the lookup table \"dm_desdobramento_2_rec\" as \"id_desdobramento_2\"",
          "message": "Row at position \"24959\" violates the foreign key: for \"id_desdobramento_2\": values \"2112\" not found in the lookup table \"dm_desdobramento_2_rec\" as \"id_desdobramento_2\"",
          "description": "Values in the foreign key fields should exist in the reference table"
        },
        {
          "cells": [
            "995",
            "4144",
            "528",
            "50",
            "963",
            "2112",
            "4025",
            "7430",
            "15648",
            "16364",
            "4",
            "23",
            "9118022202000",
            "2021",
            "-69304.52"
          ],
          "rowNumber": 24959,
          "rowPosition": 24960,
          "code": "foreign-key-error",
          "name": "ForeignKey Error",
          "tags": [
            "#table",
            "#row"
          ],
          "note": "for \"id_desdobramento_3\": values \"4025\" not found in the lookup table \"dm_desdobramento_3_rec\" as \"id_desdobramento_3\"",
          "message": "Row at position \"24960\" violates the foreign key: for \"id_desdobramento_3\": values \"4025\" not found in the lookup table \"dm_desdobramento_3_rec\" as \"id_desdobramento_3\"",
          "description": "Values in the foreign key fields should exist in the reference table"
        },
        {
          "cells": [
            "995",
            "4144",
            "528",
            "50",
            "963",
            "2112",
            "4025",
            "7430",
            "15648",
            "16364",
            "4",
            "23",
            "9118022202000",
            "2021",
            "-69304.52"
          ],
          "rowNumber": 24959,
          "rowPosition": 24960,
          "code": "foreign-key-error",
          "name": "ForeignKey Error",
          "tags": [
            "#table",
            "#row"
          ],
          "note": "for \"id_desdobramento_2\": values \"2112\" not found in the lookup table \"dm_desdobramento_2_rec\" as \"id_desdobramento_2\"",
          "message": "Row at position \"24960\" violates the foreign key: for \"id_desdobramento_2\": values \"2112\" not found in the lookup table \"dm_desdobramento_2_rec\" as \"id_desdobramento_2\"",
          "description": "Values in the foreign key fields should exist in the reference table"
        },
        {
          "cells": [
            "991",
            "4144",
            "528",
            "50",
            "963",
            "2112",
            "4025",
            "7433",
            "15654",
            "16366",
            "4",
            "23",
            "9118022302000",
            "2021",
            "-71701.79"
          ],
          "rowNumber": 24960,
          "rowPosition": 24961,
          "code": "foreign-key-error",
          "name": "ForeignKey Error",
          "tags": [
            "#table",
            "#row"
          ],
          "note": "for \"id_desdobramento_3\": values \"4025\" not found in the lookup table \"dm_desdobramento_3_rec\" as \"id_desdobramento_3\"",
          "message": "Row at position \"24961\" violates the foreign key: for \"id_desdobramento_3\": values \"4025\" not found in the lookup table \"dm_desdobramento_3_rec\" as \"id_desdobramento_3\"",
          "description": "Values in the foreign key fields should exist in the reference table"
        },
        {
          "cells": [
            "991",
            "4144",
            "528",
            "50",
            "963",
            "2112",
            "4025",
            "7433",
            "15654",
            "16366",
            "4",
            "23",
            "9118022302000",
            "2021",
            "-71701.79"
          ],
          "rowNumber": 24960,
          "rowPosition": 24961,
          "code": "foreign-key-error",
          "name": "ForeignKey Error",
          "tags": [
            "#table",
            "#row"
          ],
          "note": "for \"id_desdobramento_2\": values \"2112\" not found in the lookup table \"dm_desdobramento_2_rec\" as \"id_desdobramento_2\"",
          "message": "Row at position \"24961\" violates the foreign key: for \"id_desdobramento_2\": values \"2112\" not found in the lookup table \"dm_desdobramento_2_rec\" as \"id_desdobramento_2\"",
          "description": "Values in the foreign key fields should exist in the reference table"
        },
        {
          "cells": [
            "992",
            "4144",
            "528",
            "50",
            "963",
            "2112",
            "4025",
            "7431",
            "15652",
            "16362",
            "4",
            "23",
            "9118022402000",
            "2021",
            "-5.65"
          ],
          "rowNumber": 25488,
          "rowPosition": 25489,
          "code": "foreign-key-error",
          "name": "ForeignKey Error",
          "tags": [
            "#table",
            "#row"
          ],
          "note": "for \"id_desdobramento_3\": values \"4025\" not found in the lookup table \"dm_desdobramento_3_rec\" as \"id_desdobramento_3\"",
          "message": "Row at position \"25489\" violates the foreign key: for \"id_desdobramento_3\": values \"4025\" not found in the lookup table \"dm_desdobramento_3_rec\" as \"id_desdobramento_3\"",
          "description": "Values in the foreign key fields should exist in the reference table"
        },
        {
          "cells": [
            "992",
            "4144",
            "528",
            "50",
            "963",
            "2112",
            "4025",
            "7431",
            "15652",
            "16362",
            "4",
            "23",
            "9118022402000",
            "2021",
            "-5.65"
          ],
          "rowNumber": 25488,
          "rowPosition": 25489,
          "code": "foreign-key-error",
          "name": "ForeignKey Error",
          "tags": [
            "#table",
            "#row"
          ],
          "note": "for \"id_desdobramento_2\": values \"2112\" not found in the lookup table \"dm_desdobramento_2_rec\" as \"id_desdobramento_2\"",
          "message": "Row at position \"25489\" violates the foreign key: for \"id_desdobramento_2\": values \"2112\" not found in the lookup table \"dm_desdobramento_2_rec\" as \"id_desdobramento_2\"",
          "description": "Values in the foreign key fields should exist in the reference table"
        },
        {
          "cells": [
            "1002",
            "4224",
            "540",
            "798",
            "969",
            "2124",
            "4052",
            "7467",
            "15941",
            "16785",
            "54",
            "20",
            "9118012102000",
            "2022",
            "-152661217.87"
          ],
          "rowNumber": 25756,
          "rowPosition": 25757,
          "code": "foreign-key-error",
          "name": "ForeignKey Error",
          "tags": [
            "#table",
            "#row"
          ],
          "note": "for \"id_desdobramento_3\": values \"4052\" not found in the lookup table \"dm_desdobramento_3_rec\" as \"id_desdobramento_3\"",
          "message": "Row at position \"25757\" violates the foreign key: for \"id_desdobramento_3\": values \"4052\" not found in the lookup table \"dm_desdobramento_3_rec\" as \"id_desdobramento_3\"",
          "description": "Values in the foreign key fields should exist in the reference table"
        },
        {
          "cells": [
            "1002",
            "4224",
            "540",
            "798",
            "969",
            "2124",
            "4052",
            "7467",
            "15941",
            "16785",
            "54",
            "20",
            "9118012102000",
            "2022",
            "-152661217.87"
          ],
          "rowNumber": 25756,
          "rowPosition": 25757,
          "code": "foreign-key-error",
          "name": "ForeignKey Error",
          "tags": [
            "#table",
            "#row"
          ],
          "note": "for \"id_desdobramento_2\": values \"2124\" not found in the lookup table \"dm_desdobramento_2_rec\" as \"id_desdobramento_2\"",
          "message": "Row at position \"25757\" violates the foreign key: for \"id_desdobramento_2\": values \"2124\" not found in the lookup table \"dm_desdobramento_2_rec\" as \"id_desdobramento_2\"",
          "description": "Values in the foreign key fields should exist in the reference table"
        },
        {
          "cells": [
            "1000",
            "4224",
            "539",
            "795",
            "973",
            "2122",
            "4053",
            "7464",
            "15942",
            "16788",
            "89",
            "51",
            "9718017101002",
            "2022",
            "-5636809.38"
          ],
          "rowNumber": 25757,
          "rowPosition": 25758,
          "code": "foreign-key-error",
          "name": "ForeignKey Error",
          "tags": [
            "#table",
            "#row"
          ],
          "note": "for \"id_desdobramento_3\": values \"4053\" not found in the lookup table \"dm_desdobramento_3_rec\" as \"id_desdobramento_3\"",
          "message": "Row at position \"25758\" violates the foreign key: for \"id_desdobramento_3\": values \"4053\" not found in the lookup table \"dm_desdobramento_3_rec\" as \"id_desdobramento_3\"",
          "description": "Values in the foreign key fields should exist in the reference table"
        },
        {
          "cells": [
            "1000",
            "4224",
            "539",
            "795",
            "973",
            "2122",
            "4053",
            "7464",
            "15942",
            "16788",
            "89",
            "51",
            "9718017101002",
            "2022",
            "-5636809.38"
          ],
          "rowNumber": 25757,
          "rowPosition": 25758,
          "code": "foreign-key-error",
          "name": "ForeignKey Error",
          "tags": [
            "#table",
            "#row"
          ],
          "note": "for \"id_desdobramento_2\": values \"2122\" not found in the lookup table \"dm_desdobramento_2_rec\" as \"id_desdobramento_2\"",
          "message": "Row at position \"25758\" violates the foreign key: for \"id_desdobramento_2\": values \"2122\" not found in the lookup table \"dm_desdobramento_2_rec\" as \"id_desdobramento_2\"",
          "description": "Values in the foreign key fields should exist in the reference table"
        },
        {
          "cells": [
            "1000",
            "4224",
            "530",
            "794",
            "965",
            "2119",
            "4042",
            "7460",
            "15651",
            "16365",
            "4",
            "23",
            "9118022102000",
            "2022",
            "-11272163.54"
          ],
          "rowNumber": 25761,
          "rowPosition": 25762,
          "code": "foreign-key-error",
          "name": "ForeignKey Error",
          "tags": [
            "#table",
            "#row"
          ],
          "note": "for \"id_desdobramento_3\": values \"4042\" not found in the lookup table \"dm_desdobramento_3_rec\" as \"id_desdobramento_3\"",
          "message": "Row at position \"25762\" violates the foreign key: for \"id_desdobramento_3\": values \"4042\" not found in the lookup table \"dm_desdobramento_3_rec\" as \"id_desdobramento_3\"",
          "description": "Values in the foreign key fields should exist in the reference table"
        },
        {
          "cells": [
            "1000",
            "4224",
            "530",
            "794",
            "965",
            "2119",
            "4042",
            "7460",
            "15651",
            "16365",
            "4",
            "23",
            "9118022102000",
            "2022",
            "-11272163.54"
          ],
          "rowNumber": 25761,
          "rowPosition": 25762,
          "code": "foreign-key-error",
          "name": "ForeignKey Error",
          "tags": [
            "#table",
            "#row"
          ],
          "note": "for \"id_desdobramento_2\": values \"2119\" not found in the lookup table \"dm_desdobramento_2_rec\" as \"id_desdobramento_2\"",
          "message": "Row at position \"25762\" violates the foreign key: for \"id_desdobramento_2\": values \"2119\" not found in the lookup table \"dm_desdobramento_2_rec\" as \"id_desdobramento_2\"",
          "description": "Values in the foreign key fields should exist in the reference table"
        },
        {
          "cells": [
            "1001",
            "4224",
            "531",
            "792",
            "966",
            "2118",
            "4036",
            "7447",
            "15648",
            "16364",
            "4",
            "23",
            "9118022202000",
            "2022",
            "-36187.54"
          ],
          "rowNumber": 25762,
          "rowPosition": 25763,
          "code": "foreign-key-error",
          "name": "ForeignKey Error",
          "tags": [
            "#table",
            "#row"
          ],
          "note": "for \"id_desdobramento_3\": values \"4036\" not found in the lookup table \"dm_desdobramento_3_rec\" as \"id_desdobramento_3\"",
          "message": "Row at position \"25763\" violates the foreign key: for \"id_desdobramento_3\": values \"4036\" not found in the lookup table \"dm_desdobramento_3_rec\" as \"id_desdobramento_3\"",
          "description": "Values in the foreign key fields should exist in the reference table"
        },
        {
          "cells": [
            "1001",
            "4224",
            "531",
            "792",
            "966",
            "2118",
            "4036",
            "7447",
            "15648",
            "16364",
            "4",
            "23",
            "9118022202000",
            "2022",
            "-36187.54"
          ],
          "rowNumber": 25762,
          "rowPosition": 25763,
          "code": "foreign-key-error",
          "name": "ForeignKey Error",
          "tags": [
            "#table",
            "#row"
          ],
          "note": "for \"id_desdobramento_2\": values \"2118\" not found in the lookup table \"dm_desdobramento_2_rec\" as \"id_desdobramento_2\"",
          "message": "Row at position \"25763\" violates the foreign key: for \"id_desdobramento_2\": values \"2118\" not found in the lookup table \"dm_desdobramento_2_rec\" as \"id_desdobramento_2\"",
          "description": "Values in the foreign key fields should exist in the reference table"
        },
        {
          "cells": [
            "990",
            "4144",
            "528",
            "50",
            "963",
            "2112",
            "4025",
            "7430",
            "15648",
            "16364",
            "4",
            "23",
            "9118022202000",
            "2021",
            "-292852.43"
          ],
          "rowNumber": 25768,
          "rowPosition": 25769,
          "code": "foreign-key-error",
          "name": "ForeignKey Error",
          "tags": [
            "#table",
            "#row"
          ],
          "note": "for \"id_desdobramento_3\": values \"4025\" not found in the lookup table \"dm_desdobramento_3_rec\" as \"id_desdobramento_3\"",
          "message": "Row at position \"25769\" violates the foreign key: for \"id_desdobramento_3\": values \"4025\" not found in the lookup table \"dm_desdobramento_3_rec\" as \"id_desdobramento_3\"",
          "description": "Values in the foreign key fields should exist in the reference table"
        },
        {
          "cells": [
            "990",
            "4144",
            "528",
            "50",
            "963",
            "2112",
            "4025",
            "7430",
            "15648",
            "16364",
            "4",
            "23",
            "9118022202000",
            "2021",
            "-292852.43"
          ],
          "rowNumber": 25768,
          "rowPosition": 25769,
          "code": "foreign-key-error",
          "name": "ForeignKey Error",
          "tags": [
            "#table",
            "#row"
          ],
          "note": "for \"id_desdobramento_2\": values \"2112\" not found in the lookup table \"dm_desdobramento_2_rec\" as \"id_desdobramento_2\"",
          "message": "Row at position \"25769\" violates the foreign key: for \"id_desdobramento_2\": values \"2112\" not found in the lookup table \"dm_desdobramento_2_rec\" as \"id_desdobramento_2\"",
          "description": "Values in the foreign key fields should exist in the reference table"
        },
        {
          "cells": [
            "990",
            "4113",
            "10",
            "145",
            "173",
            "437",
            "4020",
            "7427",
            "15615",
            "16001",
            "355",
            "92",
            "1718039101000",
            "2021",
            "30000.00"
          ],
          "rowNumber": 26366,
          "rowPosition": 26367,
          "code": "foreign-key-error",
          "name": "ForeignKey Error",
          "tags": [
            "#table",
            "#row"
          ],
          "note": "for \"id_desdobramento_3\": values \"4020\" not found in the lookup table \"dm_desdobramento_3_rec\" as \"id_desdobramento_3\"",
          "message": "Row at position \"26367\" violates the foreign key: for \"id_desdobramento_3\": values \"4020\" not found in the lookup table \"dm_desdobramento_3_rec\" as \"id_desdobramento_3\"",
          "description": "Values in the foreign key fields should exist in the reference table"
        },
        {
          "cells": [
            "999",
            "4256",
            "16",
            "146",
            "153",
            "2120",
            "4026",
            "7443",
            "15877",
            "16591",
            "96",
            "70",
            "2448019109001",
            "2022",
            "0.00"
          ],
          "rowNumber": 26757,
          "rowPosition": 26758,
          "code": "foreign-key-error",
          "name": "ForeignKey Error",
          "tags": [
            "#table",
            "#row"
          ],
          "note": "for \"id_desdobramento_3\": values \"4026\" not found in the lookup table \"dm_desdobramento_3_rec\" as \"id_desdobramento_3\"",
          "message": "Row at position \"26758\" violates the foreign key: for \"id_desdobramento_3\": values \"4026\" not found in the lookup table \"dm_desdobramento_3_rec\" as \"id_desdobramento_3\"",
          "description": "Values in the foreign key fields should exist in the reference table"
        },
        {
          "cells": [
            "999",
            "4256",
            "16",
            "146",
            "153",
            "2120",
            "4026",
            "7443",
            "15877",
            "16591",
            "96",
            "70",
            "2448019109001",
            "2022",
            "0.00"
          ],
          "rowNumber": 26757,
          "rowPosition": 26758,
          "code": "foreign-key-error",
          "name": "ForeignKey Error",
          "tags": [
            "#table",
            "#row"
          ],
          "note": "for \"id_desdobramento_2\": values \"2120\" not found in the lookup table \"dm_desdobramento_2_rec\" as \"id_desdobramento_2\"",
          "message": "Row at position \"26758\" violates the foreign key: for \"id_desdobramento_2\": values \"2120\" not found in the lookup table \"dm_desdobramento_2_rec\" as \"id_desdobramento_2\"",
          "description": "Values in the foreign key fields should exist in the reference table"
        },
        {
          "cells": [
            "1001",
            "4224",
            "542",
            "800",
            "967",
            "2127",
            "4050",
            "7465",
            "15940",
            "16781",
            "54",
            "20",
            "9118012202000",
            "2022",
            "-8447370.66"
          ],
          "rowNumber": 26781,
          "rowPosition": 26782,
          "code": "foreign-key-error",
          "name": "ForeignKey Error",
          "tags": [
            "#table",
            "#row"
          ],
          "note": "for \"id_desdobramento_3\": values \"4050\" not found in the lookup table \"dm_desdobramento_3_rec\" as \"id_desdobramento_3\"",
          "message": "Row at position \"26782\" violates the foreign key: for \"id_desdobramento_3\": values \"4050\" not found in the lookup table \"dm_desdobramento_3_rec\" as \"id_desdobramento_3\"",
          "description": "Values in the foreign key fields should exist in the reference table"
        },
        {
          "cells": [
            "1001",
            "4224",
            "542",
            "800",
            "967",
            "2127",
            "4050",
            "7465",
            "15940",
            "16781",
            "54",
            "20",
            "9118012202000",
            "2022",
            "-8447370.66"
          ],
          "rowNumber": 26781,
          "rowPosition": 26782,
          "code": "foreign-key-error",
          "name": "ForeignKey Error",
          "tags": [
            "#table",
            "#row"
          ],
          "note": "for \"id_desdobramento_2\": values \"2127\" not found in the lookup table \"dm_desdobramento_2_rec\" as \"id_desdobramento_2\"",
          "message": "Row at position \"26782\" violates the foreign key: for \"id_desdobramento_2\": values \"2127\" not found in the lookup table \"dm_desdobramento_2_rec\" as \"id_desdobramento_2\"",
          "description": "Values in the foreign key fields should exist in the reference table"
        },
        {
          "cells": [
            "1002",
            "4247",
            "531",
            "792",
            "966",
            "2118",
            "4036",
            "7447",
            "15648",
            "16364",
            "4",
            "23",
            "9118022202000",
            "2022",
            "0.00"
          ],
          "rowNumber": 26783,
          "rowPosition": 26784,
          "code": "foreign-key-error",
          "name": "ForeignKey Error",
          "tags": [
            "#table",
            "#row"
          ],
          "note": "for \"id_desdobramento_3\": values \"4036\" not found in the lookup table \"dm_desdobramento_3_rec\" as \"id_desdobramento_3\"",
          "message": "Row at position \"26784\" violates the foreign key: for \"id_desdobramento_3\": values \"4036\" not found in the lookup table \"dm_desdobramento_3_rec\" as \"id_desdobramento_3\"",
          "description": "Values in the foreign key fields should exist in the reference table"
        },
        {
          "cells": [
            "1002",
            "4247",
            "531",
            "792",
            "966",
            "2118",
            "4036",
            "7447",
            "15648",
            "16364",
            "4",
            "23",
            "9118022202000",
            "2022",
            "0.00"
          ],
          "rowNumber": 26783,
          "rowPosition": 26784,
          "code": "foreign-key-error",
          "name": "ForeignKey Error",
          "tags": [
            "#table",
            "#row"
          ],
          "note": "for \"id_desdobramento_2\": values \"2118\" not found in the lookup table \"dm_desdobramento_2_rec\" as \"id_desdobramento_2\"",
          "message": "Row at position \"26784\" violates the foreign key: for \"id_desdobramento_2\": values \"2118\" not found in the lookup table \"dm_desdobramento_2_rec\" as \"id_desdobramento_2\"",
          "description": "Values in the foreign key fields should exist in the reference table"
        },
        {
          "cells": [
            "999",
            "4247",
            "531",
            "792",
            "966",
            "2118",
            "4036",
            "7447",
            "15648",
            "16364",
            "4",
            "23",
            "9118022202000",
            "2022",
            "0.00"
          ],
          "rowNumber": 26784,
          "rowPosition": 26785,
          "code": "foreign-key-error",
          "name": "ForeignKey Error",
          "tags": [
            "#table",
            "#row"
          ],
          "note": "for \"id_desdobramento_3\": values \"4036\" not found in the lookup table \"dm_desdobramento_3_rec\" as \"id_desdobramento_3\"",
          "message": "Row at position \"26785\" violates the foreign key: for \"id_desdobramento_3\": values \"4036\" not found in the lookup table \"dm_desdobramento_3_rec\" as \"id_desdobramento_3\"",
          "description": "Values in the foreign key fields should exist in the reference table"
        },
        {
          "cells": [
            "999",
            "4247",
            "531",
            "792",
            "966",
            "2118",
            "4036",
            "7447",
            "15648",
            "16364",
            "4",
            "23",
            "9118022202000",
            "2022",
            "0.00"
          ],
          "rowNumber": 26784,
          "rowPosition": 26785,
          "code": "foreign-key-error",
          "name": "ForeignKey Error",
          "tags": [
            "#table",
            "#row"
          ],
          "note": "for \"id_desdobramento_2\": values \"2118\" not found in the lookup table \"dm_desdobramento_2_rec\" as \"id_desdobramento_2\"",
          "message": "Row at position \"26785\" violates the foreign key: for \"id_desdobramento_2\": values \"2118\" not found in the lookup table \"dm_desdobramento_2_rec\" as \"id_desdobramento_2\"",
          "description": "Values in the foreign key fields should exist in the reference table"
        },
        {
          "cells": [
            "1002",
            "4247",
            "544",
            "802",
            "974",
            "2129",
            "4054",
            "7469",
            "15947",
            "16794",
            "4",
            "23",
            "9118022402000",
            "2022",
            "0.00"
          ],
          "rowNumber": 26785,
          "rowPosition": 26786,
          "code": "foreign-key-error",
          "name": "ForeignKey Error",
          "tags": [
            "#table",
            "#row"
          ],
          "note": "for \"id_desdobramento_3\": values \"4054\" not found in the lookup table \"dm_desdobramento_3_rec\" as \"id_desdobramento_3\"",
          "message": "Row at position \"26786\" violates the foreign key: for \"id_desdobramento_3\": values \"4054\" not found in the lookup table \"dm_desdobramento_3_rec\" as \"id_desdobramento_3\"",
          "description": "Values in the foreign key fields should exist in the reference table"
        },
        {
          "cells": [
            "1002",
            "4247",
            "544",
            "802",
            "974",
            "2129",
            "4054",
            "7469",
            "15947",
            "16794",
            "4",
            "23",
            "9118022402000",
            "2022",
            "0.00"
          ],
          "rowNumber": 26785,
          "rowPosition": 26786,
          "code": "foreign-key-error",
          "name": "ForeignKey Error",
          "tags": [
            "#table",
            "#row"
          ],
          "note": "for \"id_desdobramento_2\": values \"2129\" not found in the lookup table \"dm_desdobramento_2_rec\" as \"id_desdobramento_2\"",
          "message": "Row at position \"26786\" violates the foreign key: for \"id_desdobramento_2\": values \"2129\" not found in the lookup table \"dm_desdobramento_2_rec\" as \"id_desdobramento_2\"",
          "description": "Values in the foreign key fields should exist in the reference table"
        },
        {
          "cells": [
            "1000",
            "4247",
            "531",
            "792",
            "966",
            "2118",
            "4036",
            "7447",
            "15648",
            "16364",
            "4",
            "23",
            "9118022202000",
            "2022",
            "0.00"
          ],
          "rowNumber": 26927,
          "rowPosition": 26928,
          "code": "foreign-key-error",
          "name": "ForeignKey Error",
          "tags": [
            "#table",
            "#row"
          ],
          "note": "for \"id_desdobramento_3\": values \"4036\" not found in the lookup table \"dm_desdobramento_3_rec\" as \"id_desdobramento_3\"",
          "message": "Row at position \"26928\" violates the foreign key: for \"id_desdobramento_3\": values \"4036\" not found in the lookup table \"dm_desdobramento_3_rec\" as \"id_desdobramento_3\"",
          "description": "Values in the foreign key fields should exist in the reference table"
        },
        {
          "cells": [
            "1000",
            "4247",
            "531",
            "792",
            "966",
            "2118",
            "4036",
            "7447",
            "15648",
            "16364",
            "4",
            "23",
            "9118022202000",
            "2022",
            "0.00"
          ],
          "rowNumber": 26927,
          "rowPosition": 26928,
          "code": "foreign-key-error",
          "name": "ForeignKey Error",
          "tags": [
            "#table",
            "#row"
          ],
          "note": "for \"id_desdobramento_2\": values \"2118\" not found in the lookup table \"dm_desdobramento_2_rec\" as \"id_desdobramento_2\"",
          "message": "Row at position \"26928\" violates the foreign key: for \"id_desdobramento_2\": values \"2118\" not found in the lookup table \"dm_desdobramento_2_rec\" as \"id_desdobramento_2\"",
          "description": "Values in the foreign key fields should exist in the reference table"
        },
        {
          "cells": [
            "1001",
            "4247",
            "535",
            "793",
            "964",
            "2121",
            "4045",
            "7453",
            "15654",
            "16366",
            "4",
            "23",
            "9118022302000",
            "2022",
            "0.00"
          ],
          "rowNumber": 26928,
          "rowPosition": 26929,
          "code": "foreign-key-error",
          "name": "ForeignKey Error",
          "tags": [
            "#table",
            "#row"
          ],
          "note": "for \"id_desdobramento_3\": values \"4045\" not found in the lookup table \"dm_desdobramento_3_rec\" as \"id_desdobramento_3\"",
          "message": "Row at position \"26929\" violates the foreign key: for \"id_desdobramento_3\": values \"4045\" not found in the lookup table \"dm_desdobramento_3_rec\" as \"id_desdobramento_3\"",
          "description": "Values in the foreign key fields should exist in the reference table"
        },
        {
          "cells": [
            "1001",
            "4247",
            "535",
            "793",
            "964",
            "2121",
            "4045",
            "7453",
            "15654",
            "16366",
            "4",
            "23",
            "9118022302000",
            "2022",
            "0.00"
          ],
          "rowNumber": 26928,
          "rowPosition": 26929,
          "code": "foreign-key-error",
          "name": "ForeignKey Error",
          "tags": [
            "#table",
            "#row"
          ],
          "note": "for \"id_desdobramento_2\": values \"2121\" not found in the lookup table \"dm_desdobramento_2_rec\" as \"id_desdobramento_2\"",
          "message": "Row at position \"26929\" violates the foreign key: for \"id_desdobramento_2\": values \"2121\" not found in the lookup table \"dm_desdobramento_2_rec\" as \"id_desdobramento_2\"",
          "description": "Values in the foreign key fields should exist in the reference table"
        },
        {
          "cells": [
            "999",
            "4224",
            "544",
            "802",
            "974",
            "2129",
            "4054",
            "7469",
            "15947",
            "16794",
            "4",
            "23",
            "9118022402000",
            "2022",
            "-9.82"
          ],
          "rowNumber": 26931,
          "rowPosition": 26932,
          "code": "foreign-key-error",
          "name": "ForeignKey Error",
          "tags": [
            "#table",
            "#row"
          ],
          "note": "for \"id_desdobramento_3\": values \"4054\" not found in the lookup table \"dm_desdobramento_3_rec\" as \"id_desdobramento_3\"",
          "message": "Row at position \"26932\" violates the foreign key: for \"id_desdobramento_3\": values \"4054\" not found in the lookup table \"dm_desdobramento_3_rec\" as \"id_desdobramento_3\"",
          "description": "Values in the foreign key fields should exist in the reference table"
        },
        {
          "cells": [
            "999",
            "4224",
            "544",
            "802",
            "974",
            "2129",
            "4054",
            "7469",
            "15947",
            "16794",
            "4",
            "23",
            "9118022402000",
            "2022",
            "-9.82"
          ],
          "rowNumber": 26931,
          "rowPosition": 26932,
          "code": "foreign-key-error",
          "name": "ForeignKey Error",
          "tags": [
            "#table",
            "#row"
          ],
          "note": "for \"id_desdobramento_2\": values \"2129\" not found in the lookup table \"dm_desdobramento_2_rec\" as \"id_desdobramento_2\"",
          "message": "Row at position \"26932\" violates the foreign key: for \"id_desdobramento_2\": values \"2129\" not found in the lookup table \"dm_desdobramento_2_rec\" as \"id_desdobramento_2\"",
          "description": "Values in the foreign key fields should exist in the reference table"
        },
        {
          "cells": [
            "995",
            "4144",
            "528",
            "50",
            "963",
            "2112",
            "4025",
            "7431",
            "15652",
            "16362",
            "4",
            "23",
            "9118022402000",
            "2021",
            "-40.56"
          ],
          "rowNumber": 26935,
          "rowPosition": 26936,
          "code": "foreign-key-error",
          "name": "ForeignKey Error",
          "tags": [
            "#table",
            "#row"
          ],
          "note": "for \"id_desdobramento_3\": values \"4025\" not found in the lookup table \"dm_desdobramento_3_rec\" as \"id_desdobramento_3\"",
          "message": "Row at position \"26936\" violates the foreign key: for \"id_desdobramento_3\": values \"4025\" not found in the lookup table \"dm_desdobramento_3_rec\" as \"id_desdobramento_3\"",
          "description": "Values in the foreign key fields should exist in the reference table"
        },
        {
          "cells": [
            "995",
            "4144",
            "528",
            "50",
            "963",
            "2112",
            "4025",
            "7431",
            "15652",
            "16362",
            "4",
            "23",
            "9118022402000",
            "2021",
            "-40.56"
          ],
          "rowNumber": 26935,
          "rowPosition": 26936,
          "code": "foreign-key-error",
          "name": "ForeignKey Error",
          "tags": [
            "#table",
            "#row"
          ],
          "note": "for \"id_desdobramento_2\": values \"2112\" not found in the lookup table \"dm_desdobramento_2_rec\" as \"id_desdobramento_2\"",
          "message": "Row at position \"26936\" violates the foreign key: for \"id_desdobramento_2\": values \"2112\" not found in the lookup table \"dm_desdobramento_2_rec\" as \"id_desdobramento_2\"",
          "description": "Values in the foreign key fields should exist in the reference table"
        },
        {
          "cells": [
            "978",
            "4010",
            "527",
            "75",
            "962",
            "68",
            "4021",
            "7428",
            "15618",
            "16014",
            "25",
            "60",
            "9321001101000",
            "2020",
            "-2840.90"
          ],
          "rowNumber": 26965,
          "rowPosition": 26966,
          "code": "foreign-key-error",
          "name": "ForeignKey Error",
          "tags": [
            "#table",
            "#row"
          ],
          "note": "for \"id_desdobramento_3\": values \"4021\" not found in the lookup table \"dm_desdobramento_3_rec\" as \"id_desdobramento_3\"",
          "message": "Row at position \"26966\" violates the foreign key: for \"id_desdobramento_3\": values \"4021\" not found in the lookup table \"dm_desdobramento_3_rec\" as \"id_desdobramento_3\"",
          "description": "Values in the foreign key fields should exist in the reference table"
        },
        {
          "cells": [
            "1000",
            "4224",
            "544",
            "802",
            "974",
            "2129",
            "4054",
            "7469",
            "15947",
            "16794",
            "4",
            "23",
            "9118022402000",
            "2022",
            "-9.43"
          ],
          "rowNumber": 27082,
          "rowPosition": 27083,
          "code": "foreign-key-error",
          "name": "ForeignKey Error",
          "tags": [
            "#table",
            "#row"
          ],
          "note": "for \"id_desdobramento_3\": values \"4054\" not found in the lookup table \"dm_desdobramento_3_rec\" as \"id_desdobramento_3\"",
          "message": "Row at position \"27083\" violates the foreign key: for \"id_desdobramento_3\": values \"4054\" not found in the lookup table \"dm_desdobramento_3_rec\" as \"id_desdobramento_3\"",
          "description": "Values in the foreign key fields should exist in the reference table"
        },
        {
          "cells": [
            "1000",
            "4224",
            "544",
            "802",
            "974",
            "2129",
            "4054",
            "7469",
            "15947",
            "16794",
            "4",
            "23",
            "9118022402000",
            "2022",
            "-9.43"
          ],
          "rowNumber": 27082,
          "rowPosition": 27083,
          "code": "foreign-key-error",
          "name": "ForeignKey Error",
          "tags": [
            "#table",
            "#row"
          ],
          "note": "for \"id_desdobramento_2\": values \"2129\" not found in the lookup table \"dm_desdobramento_2_rec\" as \"id_desdobramento_2\"",
          "message": "Row at position \"27083\" violates the foreign key: for \"id_desdobramento_2\": values \"2129\" not found in the lookup table \"dm_desdobramento_2_rec\" as \"id_desdobramento_2\"",
          "description": "Values in the foreign key fields should exist in the reference table"
        },
        {
          "cells": [
            "1001",
            "4247",
            "544",
            "802",
            "974",
            "2129",
            "4054",
            "7469",
            "15947",
            "16794",
            "4",
            "23",
            "9118022402000",
            "2022",
            "0.00"
          ],
          "rowNumber": 27286,
          "rowPosition": 27287,
          "code": "foreign-key-error",
          "name": "ForeignKey Error",
          "tags": [
            "#table",
            "#row"
          ],
          "note": "for \"id_desdobramento_3\": values \"4054\" not found in the lookup table \"dm_desdobramento_3_rec\" as \"id_desdobramento_3\"",
          "message": "Row at position \"27287\" violates the foreign key: for \"id_desdobramento_3\": values \"4054\" not found in the lookup table \"dm_desdobramento_3_rec\" as \"id_desdobramento_3\"",
          "description": "Values in the foreign key fields should exist in the reference table"
        },
        {
          "cells": [
            "1001",
            "4247",
            "544",
            "802",
            "974",
            "2129",
            "4054",
            "7469",
            "15947",
            "16794",
            "4",
            "23",
            "9118022402000",
            "2022",
            "0.00"
          ],
          "rowNumber": 27286,
          "rowPosition": 27287,
          "code": "foreign-key-error",
          "name": "ForeignKey Error",
          "tags": [
            "#table",
            "#row"
          ],
          "note": "for \"id_desdobramento_2\": values \"2129\" not found in the lookup table \"dm_desdobramento_2_rec\" as \"id_desdobramento_2\"",
          "message": "Row at position \"27287\" violates the foreign key: for \"id_desdobramento_2\": values \"2129\" not found in the lookup table \"dm_desdobramento_2_rec\" as \"id_desdobramento_2\"",
          "description": "Values in the foreign key fields should exist in the reference table"
        },
        {
          "cells": [
            "995",
            "4144",
            "528",
            "50",
            "963",
            "2112",
            "4025",
            "7433",
            "15654",
            "16366",
            "4",
            "23",
            "9118022302000",
            "2021",
            "-22279.69"
          ],
          "rowNumber": 27291,
          "rowPosition": 27292,
          "code": "foreign-key-error",
          "name": "ForeignKey Error",
          "tags": [
            "#table",
            "#row"
          ],
          "note": "for \"id_desdobramento_3\": values \"4025\" not found in the lookup table \"dm_desdobramento_3_rec\" as \"id_desdobramento_3\"",
          "message": "Row at position \"27292\" violates the foreign key: for \"id_desdobramento_3\": values \"4025\" not found in the lookup table \"dm_desdobramento_3_rec\" as \"id_desdobramento_3\"",
          "description": "Values in the foreign key fields should exist in the reference table"
        },
        {
          "cells": [
            "995",
            "4144",
            "528",
            "50",
            "963",
            "2112",
            "4025",
            "7433",
            "15654",
            "16366",
            "4",
            "23",
            "9118022302000",
            "2021",
            "-22279.69"
          ],
          "rowNumber": 27291,
          "rowPosition": 27292,
          "code": "foreign-key-error",
          "name": "ForeignKey Error",
          "tags": [
            "#table",
            "#row"
          ],
          "note": "for \"id_desdobramento_2\": values \"2112\" not found in the lookup table \"dm_desdobramento_2_rec\" as \"id_desdobramento_2\"",
          "message": "Row at position \"27292\" violates the foreign key: for \"id_desdobramento_2\": values \"2112\" not found in the lookup table \"dm_desdobramento_2_rec\" as \"id_desdobramento_2\"",
          "description": "Values in the foreign key fields should exist in the reference table"
        },
        {
          "cells": [
            "990",
            "4144",
            "528",
            "50",
            "963",
            "2112",
            "4025",
            "7432",
            "15651",
            "16365",
            "4",
            "23",
            "9118022102000",
            "2021",
            "-84625960.14"
          ],
          "rowNumber": 27354,
          "rowPosition": 27355,
          "code": "foreign-key-error",
          "name": "ForeignKey Error",
          "tags": [
            "#table",
            "#row"
          ],
          "note": "for \"id_desdobramento_3\": values \"4025\" not found in the lookup table \"dm_desdobramento_3_rec\" as \"id_desdobramento_3\"",
          "message": "Row at position \"27355\" violates the foreign key: for \"id_desdobramento_3\": values \"4025\" not found in the lookup table \"dm_desdobramento_3_rec\" as \"id_desdobramento_3\"",
          "description": "Values in the foreign key fields should exist in the reference table"
        },
        {
          "cells": [
            "990",
            "4144",
            "528",
            "50",
            "963",
            "2112",
            "4025",
            "7432",
            "15651",
            "16365",
            "4",
            "23",
            "9118022102000",
            "2021",
            "-84625960.14"
          ],
          "rowNumber": 27354,
          "rowPosition": 27355,
          "code": "foreign-key-error",
          "name": "ForeignKey Error",
          "tags": [
            "#table",
            "#row"
          ],
          "note": "for \"id_desdobramento_2\": values \"2112\" not found in the lookup table \"dm_desdobramento_2_rec\" as \"id_desdobramento_2\"",
          "message": "Row at position \"27355\" violates the foreign key: for \"id_desdobramento_2\": values \"2112\" not found in the lookup table \"dm_desdobramento_2_rec\" as \"id_desdobramento_2\"",
          "description": "Values in the foreign key fields should exist in the reference table"
        },
        {
          "cells": [
            "992",
            "4144",
            "528",
            "50",
            "963",
            "2112",
            "4025",
            "7430",
            "15648",
            "16364",
            "4",
            "23",
            "9118022202000",
            "2021",
            "-36581.15"
          ],
          "rowNumber": 27355,
          "rowPosition": 27356,
          "code": "foreign-key-error",
          "name": "ForeignKey Error",
          "tags": [
            "#table",
            "#row"
          ],
          "note": "for \"id_desdobramento_3\": values \"4025\" not found in the lookup table \"dm_desdobramento_3_rec\" as \"id_desdobramento_3\"",
          "message": "Row at position \"27356\" violates the foreign key: for \"id_desdobramento_3\": values \"4025\" not found in the lookup table \"dm_desdobramento_3_rec\" as \"id_desdobramento_3\"",
          "description": "Values in the foreign key fields should exist in the reference table"
        },
        {
          "cells": [
            "992",
            "4144",
            "528",
            "50",
            "963",
            "2112",
            "4025",
            "7430",
            "15648",
            "16364",
            "4",
            "23",
            "9118022202000",
            "2021",
            "-36581.15"
          ],
          "rowNumber": 27355,
          "rowPosition": 27356,
          "code": "foreign-key-error",
          "name": "ForeignKey Error",
          "tags": [
            "#table",
            "#row"
          ],
          "note": "for \"id_desdobramento_2\": values \"2112\" not found in the lookup table \"dm_desdobramento_2_rec\" as \"id_desdobramento_2\"",
          "message": "Row at position \"27356\" violates the foreign key: for \"id_desdobramento_2\": values \"2112\" not found in the lookup table \"dm_desdobramento_2_rec\" as \"id_desdobramento_2\"",
          "description": "Values in the foreign key fields should exist in the reference table"
        },
        {
          "cells": [
            "993",
            "4144",
            "528",
            "50",
            "963",
            "2112",
            "4025",
            "7431",
            "15652",
            "16362",
            "4",
            "23",
            "9118022402000",
            "2021",
            "-27.88"
          ],
          "rowNumber": 27356,
          "rowPosition": 27357,
          "code": "foreign-key-error",
          "name": "ForeignKey Error",
          "tags": [
            "#table",
            "#row"
          ],
          "note": "for \"id_desdobramento_3\": values \"4025\" not found in the lookup table \"dm_desdobramento_3_rec\" as \"id_desdobramento_3\"",
          "message": "Row at position \"27357\" violates the foreign key: for \"id_desdobramento_3\": values \"4025\" not found in the lookup table \"dm_desdobramento_3_rec\" as \"id_desdobramento_3\"",
          "description": "Values in the foreign key fields should exist in the reference table"
        },
        {
          "cells": [
            "993",
            "4144",
            "528",
            "50",
            "963",
            "2112",
            "4025",
            "7431",
            "15652",
            "16362",
            "4",
            "23",
            "9118022402000",
            "2021",
            "-27.88"
          ],
          "rowNumber": 27356,
          "rowPosition": 27357,
          "code": "foreign-key-error",
          "name": "ForeignKey Error",
          "tags": [
            "#table",
            "#row"
          ],
          "note": "for \"id_desdobramento_2\": values \"2112\" not found in the lookup table \"dm_desdobramento_2_rec\" as \"id_desdobramento_2\"",
          "message": "Row at position \"27357\" violates the foreign key: for \"id_desdobramento_2\": values \"2112\" not found in the lookup table \"dm_desdobramento_2_rec\" as \"id_desdobramento_2\"",
          "description": "Values in the foreign key fields should exist in the reference table"
        },
        {
          "cells": [
            "988",
            "4113",
            "10",
            "145",
            "173",
            "437",
            "4020",
            "7427",
            "15615",
            "16001",
            "355",
            "92",
            "1718039101000",
            "2021",
            "1101988.00"
          ],
          "rowNumber": 27488,
          "rowPosition": 27489,
          "code": "foreign-key-error",
          "name": "ForeignKey Error",
          "tags": [
            "#table",
            "#row"
          ],
          "note": "for \"id_desdobramento_3\": values \"4020\" not found in the lookup table \"dm_desdobramento_3_rec\" as \"id_desdobramento_3\"",
          "message": "Row at position \"27489\" violates the foreign key: for \"id_desdobramento_3\": values \"4020\" not found in the lookup table \"dm_desdobramento_3_rec\" as \"id_desdobramento_3\"",
          "description": "Values in the foreign key fields should exist in the reference table"
        },
        {
          "cells": [
            "1001",
            "4224",
            "540",
            "798",
            "969",
            "2124",
            "4052",
            "7467",
            "15941",
            "16785",
            "54",
            "20",
            "9118012102000",
            "2022",
            "-1336575611.13"
          ],
          "rowNumber": 28091,
          "rowPosition": 28092,
          "code": "foreign-key-error",
          "name": "ForeignKey Error",
          "tags": [
            "#table",
            "#row"
          ],
          "note": "for \"id_desdobramento_3\": values \"4052\" not found in the lookup table \"dm_desdobramento_3_rec\" as \"id_desdobramento_3\"",
          "message": "Row at position \"28092\" violates the foreign key: for \"id_desdobramento_3\": values \"4052\" not found in the lookup table \"dm_desdobramento_3_rec\" as \"id_desdobramento_3\"",
          "description": "Values in the foreign key fields should exist in the reference table"
        },
        {
          "cells": [
            "1001",
            "4224",
            "540",
            "798",
            "969",
            "2124",
            "4052",
            "7467",
            "15941",
            "16785",
            "54",
            "20",
            "9118012102000",
            "2022",
            "-1336575611.13"
          ],
          "rowNumber": 28091,
          "rowPosition": 28092,
          "code": "foreign-key-error",
          "name": "ForeignKey Error",
          "tags": [
            "#table",
            "#row"
          ],
          "note": "for \"id_desdobramento_2\": values \"2124\" not found in the lookup table \"dm_desdobramento_2_rec\" as \"id_desdobramento_2\"",
          "message": "Row at position \"28092\" violates the foreign key: for \"id_desdobramento_2\": values \"2124\" not found in the lookup table \"dm_desdobramento_2_rec\" as \"id_desdobramento_2\"",
          "description": "Values in the foreign key fields should exist in the reference table"
        },
        {
          "cells": [
            "999",
            "4224",
            "539",
            "795",
            "973",
            "2122",
            "4053",
            "7464",
            "15942",
            "16788",
            "89",
            "51",
            "9718017101002",
            "2022",
            "0.00"
          ],
          "rowNumber": 28092,
          "rowPosition": 28093,
          "code": "foreign-key-error",
          "name": "ForeignKey Error",
          "tags": [
            "#table",
            "#row"
          ],
          "note": "for \"id_desdobramento_3\": values \"4053\" not found in the lookup table \"dm_desdobramento_3_rec\" as \"id_desdobramento_3\"",
          "message": "Row at position \"28093\" violates the foreign key: for \"id_desdobramento_3\": values \"4053\" not found in the lookup table \"dm_desdobramento_3_rec\" as \"id_desdobramento_3\"",
          "description": "Values in the foreign key fields should exist in the reference table"
        },
        {
          "cells": [
            "999",
            "4224",
            "539",
            "795",
            "973",
            "2122",
            "4053",
            "7464",
            "15942",
            "16788",
            "89",
            "51",
            "9718017101002",
            "2022",
            "0.00"
          ],
          "rowNumber": 28092,
          "rowPosition": 28093,
          "code": "foreign-key-error",
          "name": "ForeignKey Error",
          "tags": [
            "#table",
            "#row"
          ],
          "note": "for \"id_desdobramento_2\": values \"2122\" not found in the lookup table \"dm_desdobramento_2_rec\" as \"id_desdobramento_2\"",
          "message": "Row at position \"28093\" violates the foreign key: for \"id_desdobramento_2\": values \"2122\" not found in the lookup table \"dm_desdobramento_2_rec\" as \"id_desdobramento_2\"",
          "description": "Values in the foreign key fields should exist in the reference table"
        },
        {
          "cells": [
            "999",
            "4247",
            "530",
            "794",
            "965",
            "2119",
            "4042",
            "7460",
            "15651",
            "16365",
            "4",
            "23",
            "9118022102000",
            "2022",
            "0.00"
          ],
          "rowNumber": 28095,
          "rowPosition": 28096,
          "code": "foreign-key-error",
          "name": "ForeignKey Error",
          "tags": [
            "#table",
            "#row"
          ],
          "note": "for \"id_desdobramento_3\": values \"4042\" not found in the lookup table \"dm_desdobramento_3_rec\" as \"id_desdobramento_3\"",
          "message": "Row at position \"28096\" violates the foreign key: for \"id_desdobramento_3\": values \"4042\" not found in the lookup table \"dm_desdobramento_3_rec\" as \"id_desdobramento_3\"",
          "description": "Values in the foreign key fields should exist in the reference table"
        },
        {
          "cells": [
            "999",
            "4247",
            "530",
            "794",
            "965",
            "2119",
            "4042",
            "7460",
            "15651",
            "16365",
            "4",
            "23",
            "9118022102000",
            "2022",
            "0.00"
          ],
          "rowNumber": 28095,
          "rowPosition": 28096,
          "code": "foreign-key-error",
          "name": "ForeignKey Error",
          "tags": [
            "#table",
            "#row"
          ],
          "note": "for \"id_desdobramento_2\": values \"2119\" not found in the lookup table \"dm_desdobramento_2_rec\" as \"id_desdobramento_2\"",
          "message": "Row at position \"28096\" violates the foreign key: for \"id_desdobramento_2\": values \"2119\" not found in the lookup table \"dm_desdobramento_2_rec\" as \"id_desdobramento_2\"",
          "description": "Values in the foreign key fields should exist in the reference table"
        },
        {
          "cells": [
            "1001",
            "4224",
            "544",
            "802",
            "974",
            "2129",
            "4054",
            "7469",
            "15947",
            "16794",
            "4",
            "23",
            "9118022402000",
            "2022",
            "-19.03"
          ],
          "rowNumber": 28096,
          "rowPosition": 28097,
          "code": "foreign-key-error",
          "name": "ForeignKey Error",
          "tags": [
            "#table",
            "#row"
          ],
          "note": "for \"id_desdobramento_3\": values \"4054\" not found in the lookup table \"dm_desdobramento_3_rec\" as \"id_desdobramento_3\"",
          "message": "Row at position \"28097\" violates the foreign key: for \"id_desdobramento_3\": values \"4054\" not found in the lookup table \"dm_desdobramento_3_rec\" as \"id_desdobramento_3\"",
          "description": "Values in the foreign key fields should exist in the reference table"
        },
        {
          "cells": [
            "1001",
            "4224",
            "544",
            "802",
            "974",
            "2129",
            "4054",
            "7469",
            "15947",
            "16794",
            "4",
            "23",
            "9118022402000",
            "2022",
            "-19.03"
          ],
          "rowNumber": 28096,
          "rowPosition": 28097,
          "code": "foreign-key-error",
          "name": "ForeignKey Error",
          "tags": [
            "#table",
            "#row"
          ],
          "note": "for \"id_desdobramento_2\": values \"2129\" not found in the lookup table \"dm_desdobramento_2_rec\" as \"id_desdobramento_2\"",
          "message": "Row at position \"28097\" violates the foreign key: for \"id_desdobramento_2\": values \"2129\" not found in the lookup table \"dm_desdobramento_2_rec\" as \"id_desdobramento_2\"",
          "description": "Values in the foreign key fields should exist in the reference table"
        },
        {
          "cells": [
            "1000",
            "4224",
            "542",
            "800",
            "967",
            "2127",
            "4050",
            "7465",
            "15940",
            "16781",
            "54",
            "20",
            "9118012202000",
            "2022",
            "-5476271.97"
          ],
          "rowNumber": 28390,
          "rowPosition": 28391,
          "code": "foreign-key-error",
          "name": "ForeignKey Error",
          "tags": [
            "#table",
            "#row"
          ],
          "note": "for \"id_desdobramento_3\": values \"4050\" not found in the lookup table \"dm_desdobramento_3_rec\" as \"id_desdobramento_3\"",
          "message": "Row at position \"28391\" violates the foreign key: for \"id_desdobramento_3\": values \"4050\" not found in the lookup table \"dm_desdobramento_3_rec\" as \"id_desdobramento_3\"",
          "description": "Values in the foreign key fields should exist in the reference table"
        },
        {
          "cells": [
            "1000",
            "4224",
            "542",
            "800",
            "967",
            "2127",
            "4050",
            "7465",
            "15940",
            "16781",
            "54",
            "20",
            "9118012202000",
            "2022",
            "-5476271.97"
          ],
          "rowNumber": 28390,
          "rowPosition": 28391,
          "code": "foreign-key-error",
          "name": "ForeignKey Error",
          "tags": [
            "#table",
            "#row"
          ],
          "note": "for \"id_desdobramento_2\": values \"2127\" not found in the lookup table \"dm_desdobramento_2_rec\" as \"id_desdobramento_2\"",
          "message": "Row at position \"28391\" violates the foreign key: for \"id_desdobramento_2\": values \"2127\" not found in the lookup table \"dm_desdobramento_2_rec\" as \"id_desdobramento_2\"",
          "description": "Values in the foreign key fields should exist in the reference table"
        },
        {
          "cells": [
            "1001",
            "4224",
            "535",
            "793",
            "964",
            "2121",
            "4045",
            "7453",
            "15654",
            "16366",
            "4",
            "23",
            "9118022302000",
            "2022",
            "-17807.48"
          ],
          "rowNumber": 28395,
          "rowPosition": 28396,
          "code": "foreign-key-error",
          "name": "ForeignKey Error",
          "tags": [
            "#table",
            "#row"
          ],
          "note": "for \"id_desdobramento_3\": values \"4045\" not found in the lookup table \"dm_desdobramento_3_rec\" as \"id_desdobramento_3\"",
          "message": "Row at position \"28396\" violates the foreign key: for \"id_desdobramento_3\": values \"4045\" not found in the lookup table \"dm_desdobramento_3_rec\" as \"id_desdobramento_3\"",
          "description": "Values in the foreign key fields should exist in the reference table"
        },
        {
          "cells": [
            "1001",
            "4224",
            "535",
            "793",
            "964",
            "2121",
            "4045",
            "7453",
            "15654",
            "16366",
            "4",
            "23",
            "9118022302000",
            "2022",
            "-17807.48"
          ],
          "rowNumber": 28395,
          "rowPosition": 28396,
          "code": "foreign-key-error",
          "name": "ForeignKey Error",
          "tags": [
            "#table",
            "#row"
          ],
          "note": "for \"id_desdobramento_2\": values \"2121\" not found in the lookup table \"dm_desdobramento_2_rec\" as \"id_desdobramento_2\"",
          "message": "Row at position \"28396\" violates the foreign key: for \"id_desdobramento_2\": values \"2121\" not found in the lookup table \"dm_desdobramento_2_rec\" as \"id_desdobramento_2\"",
          "description": "Values in the foreign key fields should exist in the reference table"
        },
        {
          "cells": [
            "1000",
            "4224",
            "541",
            "799",
            "971",
            "2125",
            "4048",
            "7468",
            "15939",
            "16782",
            "54",
            "20",
            "9118012302000",
            "2022",
            "-3904523.02"
          ],
          "rowNumber": 28588,
          "rowPosition": 28589,
          "code": "foreign-key-error",
          "name": "ForeignKey Error",
          "tags": [
            "#table",
            "#row"
          ],
          "note": "for \"id_desdobramento_3\": values \"4048\" not found in the lookup table \"dm_desdobramento_3_rec\" as \"id_desdobramento_3\"",
          "message": "Row at position \"28589\" violates the foreign key: for \"id_desdobramento_3\": values \"4048\" not found in the lookup table \"dm_desdobramento_3_rec\" as \"id_desdobramento_3\"",
          "description": "Values in the foreign key fields should exist in the reference table"
        },
        {
          "cells": [
            "1000",
            "4224",
            "541",
            "799",
            "971",
            "2125",
            "4048",
            "7468",
            "15939",
            "16782",
            "54",
            "20",
            "9118012302000",
            "2022",
            "-3904523.02"
          ],
          "rowNumber": 28588,
          "rowPosition": 28589,
          "code": "foreign-key-error",
          "name": "ForeignKey Error",
          "tags": [
            "#table",
            "#row"
          ],
          "note": "for \"id_desdobramento_2\": values \"2125\" not found in the lookup table \"dm_desdobramento_2_rec\" as \"id_desdobramento_2\"",
          "message": "Row at position \"28589\" violates the foreign key: for \"id_desdobramento_2\": values \"2125\" not found in the lookup table \"dm_desdobramento_2_rec\" as \"id_desdobramento_2\"",
          "description": "Values in the foreign key fields should exist in the reference table"
        },
        {
          "cells": [
            "999",
            "4224",
            "538",
            "796",
            "972",
            "2123",
            "4051",
            "7466",
            "15943",
            "16787",
            "54",
            "20",
            "9718016101002",
            "2022",
            "-20372232.92"
          ],
          "rowNumber": 28589,
          "rowPosition": 28590,
          "code": "foreign-key-error",
          "name": "ForeignKey Error",
          "tags": [
            "#table",
            "#row"
          ],
          "note": "for \"id_desdobramento_3\": values \"4051\" not found in the lookup table \"dm_desdobramento_3_rec\" as \"id_desdobramento_3\"",
          "message": "Row at position \"28590\" violates the foreign key: for \"id_desdobramento_3\": values \"4051\" not found in the lookup table \"dm_desdobramento_3_rec\" as \"id_desdobramento_3\"",
          "description": "Values in the foreign key fields should exist in the reference table"
        },
        {
          "cells": [
            "999",
            "4224",
            "538",
            "796",
            "972",
            "2123",
            "4051",
            "7466",
            "15943",
            "16787",
            "54",
            "20",
            "9718016101002",
            "2022",
            "-20372232.92"
          ],
          "rowNumber": 28589,
          "rowPosition": 28590,
          "code": "foreign-key-error",
          "name": "ForeignKey Error",
          "tags": [
            "#table",
            "#row"
          ],
          "note": "for \"id_desdobramento_2\": values \"2123\" not found in the lookup table \"dm_desdobramento_2_rec\" as \"id_desdobramento_2\"",
          "message": "Row at position \"28590\" violates the foreign key: for \"id_desdobramento_2\": values \"2123\" not found in the lookup table \"dm_desdobramento_2_rec\" as \"id_desdobramento_2\"",
          "description": "Values in the foreign key fields should exist in the reference table"
        },
        {
          "cells": [
            "1000",
            "4224",
            "538",
            "796",
            "972",
            "2123",
            "4051",
            "7466",
            "15943",
            "16787",
            "54",
            "20",
            "9718016101002",
            "2022",
            "-18216073.43"
          ],
          "rowNumber": 29715,
          "rowPosition": 29716,
          "code": "foreign-key-error",
          "name": "ForeignKey Error",
          "tags": [
            "#table",
            "#row"
          ],
          "note": "for \"id_desdobramento_3\": values \"4051\" not found in the lookup table \"dm_desdobramento_3_rec\" as \"id_desdobramento_3\"",
          "message": "Row at position \"29716\" violates the foreign key: for \"id_desdobramento_3\": values \"4051\" not found in the lookup table \"dm_desdobramento_3_rec\" as \"id_desdobramento_3\"",
          "description": "Values in the foreign key fields should exist in the reference table"
        },
        {
          "cells": [
            "1000",
            "4224",
            "538",
            "796",
            "972",
            "2123",
            "4051",
            "7466",
            "15943",
            "16787",
            "54",
            "20",
            "9718016101002",
            "2022",
            "-18216073.43"
          ],
          "rowNumber": 29715,
          "rowPosition": 29716,
          "code": "foreign-key-error",
          "name": "ForeignKey Error",
          "tags": [
            "#table",
            "#row"
          ],
          "note": "for \"id_desdobramento_2\": values \"2123\" not found in the lookup table \"dm_desdobramento_2_rec\" as \"id_desdobramento_2\"",
          "message": "Row at position \"29716\" violates the foreign key: for \"id_desdobramento_2\": values \"2123\" not found in the lookup table \"dm_desdobramento_2_rec\" as \"id_desdobramento_2\"",
          "description": "Values in the foreign key fields should exist in the reference table"
        },
        {
          "cells": [
            "1000",
            "4247",
            "530",
            "794",
            "965",
            "2119",
            "4042",
            "7460",
            "15651",
            "16365",
            "4",
            "23",
            "9118022102000",
            "2022",
            "0.00"
          ],
          "rowNumber": 29765,
          "rowPosition": 29766,
          "code": "foreign-key-error",
          "name": "ForeignKey Error",
          "tags": [
            "#table",
            "#row"
          ],
          "note": "for \"id_desdobramento_3\": values \"4042\" not found in the lookup table \"dm_desdobramento_3_rec\" as \"id_desdobramento_3\"",
          "message": "Row at position \"29766\" violates the foreign key: for \"id_desdobramento_3\": values \"4042\" not found in the lookup table \"dm_desdobramento_3_rec\" as \"id_desdobramento_3\"",
          "description": "Values in the foreign key fields should exist in the reference table"
        },
        {
          "cells": [
            "1000",
            "4247",
            "530",
            "794",
            "965",
            "2119",
            "4042",
            "7460",
            "15651",
            "16365",
            "4",
            "23",
            "9118022102000",
            "2022",
            "0.00"
          ],
          "rowNumber": 29765,
          "rowPosition": 29766,
          "code": "foreign-key-error",
          "name": "ForeignKey Error",
          "tags": [
            "#table",
            "#row"
          ],
          "note": "for \"id_desdobramento_2\": values \"2119\" not found in the lookup table \"dm_desdobramento_2_rec\" as \"id_desdobramento_2\"",
          "message": "Row at position \"29766\" violates the foreign key: for \"id_desdobramento_2\": values \"2119\" not found in the lookup table \"dm_desdobramento_2_rec\" as \"id_desdobramento_2\"",
          "description": "Values in the foreign key fields should exist in the reference table"
        },
        {
          "cells": [
            "994",
            "4144",
            "528",
            "50",
            "963",
            "2112",
            "4025",
            "7431",
            "15652",
            "16362",
            "4",
            "23",
            "9118022402000",
            "2021",
            "-51.54"
          ],
          "rowNumber": 29770,
          "rowPosition": 29771,
          "code": "foreign-key-error",
          "name": "ForeignKey Error",
          "tags": [
            "#table",
            "#row"
          ],
          "note": "for \"id_desdobramento_3\": values \"4025\" not found in the lookup table \"dm_desdobramento_3_rec\" as \"id_desdobramento_3\"",
          "message": "Row at position \"29771\" violates the foreign key: for \"id_desdobramento_3\": values \"4025\" not found in the lookup table \"dm_desdobramento_3_rec\" as \"id_desdobramento_3\"",
          "description": "Values in the foreign key fields should exist in the reference table"
        },
        {
          "cells": [
            "994",
            "4144",
            "528",
            "50",
            "963",
            "2112",
            "4025",
            "7431",
            "15652",
            "16362",
            "4",
            "23",
            "9118022402000",
            "2021",
            "-51.54"
          ],
          "rowNumber": 29770,
          "rowPosition": 29771,
          "code": "foreign-key-error",
          "name": "ForeignKey Error",
          "tags": [
            "#table",
            "#row"
          ],
          "note": "for \"id_desdobramento_2\": values \"2112\" not found in the lookup table \"dm_desdobramento_2_rec\" as \"id_desdobramento_2\"",
          "message": "Row at position \"29771\" violates the foreign key: for \"id_desdobramento_2\": values \"2112\" not found in the lookup table \"dm_desdobramento_2_rec\" as \"id_desdobramento_2\"",
          "description": "Values in the foreign key fields should exist in the reference table"
        },
        {
          "cells": [
            "999",
            "4256",
            "10",
            "146",
            "153",
            "2115",
            "4026",
            "7443",
            "15877",
            "16398",
            "96",
            "70",
            "1748019109003",
            "2022",
            "0.00"
          ],
          "rowNumber": 30024,
          "rowPosition": 30025,
          "code": "foreign-key-error",
          "name": "ForeignKey Error",
          "tags": [
            "#table",
            "#row"
          ],
          "note": "for \"id_desdobramento_3\": values \"4026\" not found in the lookup table \"dm_desdobramento_3_rec\" as \"id_desdobramento_3\"",
          "message": "Row at position \"30025\" violates the foreign key: for \"id_desdobramento_3\": values \"4026\" not found in the lookup table \"dm_desdobramento_3_rec\" as \"id_desdobramento_3\"",
          "description": "Values in the foreign key fields should exist in the reference table"
        },
        {
          "cells": [
            "999",
            "4256",
            "10",
            "146",
            "153",
            "2115",
            "4026",
            "7443",
            "15877",
            "16398",
            "96",
            "70",
            "1748019109003",
            "2022",
            "0.00"
          ],
          "rowNumber": 30024,
          "rowPosition": 30025,
          "code": "foreign-key-error",
          "name": "ForeignKey Error",
          "tags": [
            "#table",
            "#row"
          ],
          "note": "for \"id_desdobramento_2\": values \"2115\" not found in the lookup table \"dm_desdobramento_2_rec\" as \"id_desdobramento_2\"",
          "message": "Row at position \"30025\" violates the foreign key: for \"id_desdobramento_2\": values \"2115\" not found in the lookup table \"dm_desdobramento_2_rec\" as \"id_desdobramento_2\"",
          "description": "Values in the foreign key fields should exist in the reference table"
        },
        {
          "cells": [
            "1002",
            "4224",
            "530",
            "794",
            "965",
            "2119",
            "4042",
            "7460",
            "15651",
            "16365",
            "4",
            "23",
            "9118022102000",
            "2022",
            "-14374857.81"
          ],
          "rowNumber": 30265,
          "rowPosition": 30266,
          "code": "foreign-key-error",
          "name": "ForeignKey Error",
          "tags": [
            "#table",
            "#row"
          ],
          "note": "for \"id_desdobramento_3\": values \"4042\" not found in the lookup table \"dm_desdobramento_3_rec\" as \"id_desdobramento_3\"",
          "message": "Row at position \"30266\" violates the foreign key: for \"id_desdobramento_3\": values \"4042\" not found in the lookup table \"dm_desdobramento_3_rec\" as \"id_desdobramento_3\"",
          "description": "Values in the foreign key fields should exist in the reference table"
        },
        {
          "cells": [
            "1002",
            "4224",
            "530",
            "794",
            "965",
            "2119",
            "4042",
            "7460",
            "15651",
            "16365",
            "4",
            "23",
            "9118022102000",
            "2022",
            "-14374857.81"
          ],
          "rowNumber": 30265,
          "rowPosition": 30266,
          "code": "foreign-key-error",
          "name": "ForeignKey Error",
          "tags": [
            "#table",
            "#row"
          ],
          "note": "for \"id_desdobramento_2\": values \"2119\" not found in the lookup table \"dm_desdobramento_2_rec\" as \"id_desdobramento_2\"",
          "message": "Row at position \"30266\" violates the foreign key: for \"id_desdobramento_2\": values \"2119\" not found in the lookup table \"dm_desdobramento_2_rec\" as \"id_desdobramento_2\"",
          "description": "Values in the foreign key fields should exist in the reference table"
        },
        {
          "cells": [
            "1001",
            "4224",
            "530",
            "794",
            "965",
            "2119",
            "4042",
            "7460",
            "15651",
            "16365",
            "4",
            "23",
            "9118022102000",
            "2022",
            "-12316023.01"
          ],
          "rowNumber": 30266,
          "rowPosition": 30267,
          "code": "foreign-key-error",
          "name": "ForeignKey Error",
          "tags": [
            "#table",
            "#row"
          ],
          "note": "for \"id_desdobramento_3\": values \"4042\" not found in the lookup table \"dm_desdobramento_3_rec\" as \"id_desdobramento_3\"",
          "message": "Row at position \"30267\" violates the foreign key: for \"id_desdobramento_3\": values \"4042\" not found in the lookup table \"dm_desdobramento_3_rec\" as \"id_desdobramento_3\"",
          "description": "Values in the foreign key fields should exist in the reference table"
        },
        {
          "cells": [
            "1001",
            "4224",
            "530",
            "794",
            "965",
            "2119",
            "4042",
            "7460",
            "15651",
            "16365",
            "4",
            "23",
            "9118022102000",
            "2022",
            "-12316023.01"
          ],
          "rowNumber": 30266,
          "rowPosition": 30267,
          "code": "foreign-key-error",
          "name": "ForeignKey Error",
          "tags": [
            "#table",
            "#row"
          ],
          "note": "for \"id_desdobramento_2\": values \"2119\" not found in the lookup table \"dm_desdobramento_2_rec\" as \"id_desdobramento_2\"",
          "message": "Row at position \"30267\" violates the foreign key: for \"id_desdobramento_2\": values \"2119\" not found in the lookup table \"dm_desdobramento_2_rec\" as \"id_desdobramento_2\"",
          "description": "Values in the foreign key fields should exist in the reference table"
        },
        {
          "cells": [
            "992",
            "4144",
            "528",
            "50",
            "963",
            "2112",
            "4025",
            "7433",
            "15654",
            "16366",
            "4",
            "23",
            "9118022302000",
            "2021",
            "-15028.98"
          ],
          "rowNumber": 30275,
          "rowPosition": 30276,
          "code": "foreign-key-error",
          "name": "ForeignKey Error",
          "tags": [
            "#table",
            "#row"
          ],
          "note": "for \"id_desdobramento_3\": values \"4025\" not found in the lookup table \"dm_desdobramento_3_rec\" as \"id_desdobramento_3\"",
          "message": "Row at position \"30276\" violates the foreign key: for \"id_desdobramento_3\": values \"4025\" not found in the lookup table \"dm_desdobramento_3_rec\" as \"id_desdobramento_3\"",
          "description": "Values in the foreign key fields should exist in the reference table"
        },
        {
          "cells": [
            "992",
            "4144",
            "528",
            "50",
            "963",
            "2112",
            "4025",
            "7433",
            "15654",
            "16366",
            "4",
            "23",
            "9118022302000",
            "2021",
            "-15028.98"
          ],
          "rowNumber": 30275,
          "rowPosition": 30276,
          "code": "foreign-key-error",
          "name": "ForeignKey Error",
          "tags": [
            "#table",
            "#row"
          ],
          "note": "for \"id_desdobramento_2\": values \"2112\" not found in the lookup table \"dm_desdobramento_2_rec\" as \"id_desdobramento_2\"",
          "message": "Row at position \"30276\" violates the foreign key: for \"id_desdobramento_2\": values \"2112\" not found in the lookup table \"dm_desdobramento_2_rec\" as \"id_desdobramento_2\"",
          "description": "Values in the foreign key fields should exist in the reference table"
        },
        {
          "cells": [
            "1001",
            "4224",
            "538",
            "796",
            "972",
            "2123",
            "4051",
            "7466",
            "15943",
            "16787",
            "54",
            "20",
            "9718016101002",
            "2022",
            "-20636935.82"
          ],
          "rowNumber": 30374,
          "rowPosition": 30375,
          "code": "foreign-key-error",
          "name": "ForeignKey Error",
          "tags": [
            "#table",
            "#row"
          ],
          "note": "for \"id_desdobramento_3\": values \"4051\" not found in the lookup table \"dm_desdobramento_3_rec\" as \"id_desdobramento_3\"",
          "message": "Row at position \"30375\" violates the foreign key: for \"id_desdobramento_3\": values \"4051\" not found in the lookup table \"dm_desdobramento_3_rec\" as \"id_desdobramento_3\"",
          "description": "Values in the foreign key fields should exist in the reference table"
        },
        {
          "cells": [
            "1001",
            "4224",
            "538",
            "796",
            "972",
            "2123",
            "4051",
            "7466",
            "15943",
            "16787",
            "54",
            "20",
            "9718016101002",
            "2022",
            "-20636935.82"
          ],
          "rowNumber": 30374,
          "rowPosition": 30375,
          "code": "foreign-key-error",
          "name": "ForeignKey Error",
          "tags": [
            "#table",
            "#row"
          ],
          "note": "for \"id_desdobramento_2\": values \"2123\" not found in the lookup table \"dm_desdobramento_2_rec\" as \"id_desdobramento_2\"",
          "message": "Row at position \"30375\" violates the foreign key: for \"id_desdobramento_2\": values \"2123\" not found in the lookup table \"dm_desdobramento_2_rec\" as \"id_desdobramento_2\"",
          "description": "Values in the foreign key fields should exist in the reference table"
        },
        {
          "cells": [
            "993",
            "4144",
            "528",
            "50",
            "963",
            "2112",
            "4025",
            "7433",
            "15654",
            "16366",
            "4",
            "23",
            "9118022302000",
            "2021",
            "-20729.41"
          ],
          "rowNumber": 30382,
          "rowPosition": 30383,
          "code": "foreign-key-error",
          "name": "ForeignKey Error",
          "tags": [
            "#table",
            "#row"
          ],
          "note": "for \"id_desdobramento_3\": values \"4025\" not found in the lookup table \"dm_desdobramento_3_rec\" as \"id_desdobramento_3\"",
          "message": "Row at position \"30383\" violates the foreign key: for \"id_desdobramento_3\": values \"4025\" not found in the lookup table \"dm_desdobramento_3_rec\" as \"id_desdobramento_3\"",
          "description": "Values in the foreign key fields should exist in the reference table"
        },
        {
          "cells": [
            "993",
            "4144",
            "528",
            "50",
            "963",
            "2112",
            "4025",
            "7433",
            "15654",
            "16366",
            "4",
            "23",
            "9118022302000",
            "2021",
            "-20729.41"
          ],
          "rowNumber": 30382,
          "rowPosition": 30383,
          "code": "foreign-key-error",
          "name": "ForeignKey Error",
          "tags": [
            "#table",
            "#row"
          ],
          "note": "for \"id_desdobramento_2\": values \"2112\" not found in the lookup table \"dm_desdobramento_2_rec\" as \"id_desdobramento_2\"",
          "message": "Row at position \"30383\" violates the foreign key: for \"id_desdobramento_2\": values \"2112\" not found in the lookup table \"dm_desdobramento_2_rec\" as \"id_desdobramento_2\"",
          "description": "Values in the foreign key fields should exist in the reference table"
        },
        {
          "cells": [
            "985",
            "4113",
            "10",
            "145",
            "173",
            "437",
            "4020",
            "7427",
            "15615",
            "16001",
            "355",
            "92",
            "1718039101000",
            "2021",
            "0.00"
          ],
          "rowNumber": 30481,
          "rowPosition": 30482,
          "code": "foreign-key-error",
          "name": "ForeignKey Error",
          "tags": [
            "#table",
            "#row"
          ],
          "note": "for \"id_desdobramento_3\": values \"4020\" not found in the lookup table \"dm_desdobramento_3_rec\" as \"id_desdobramento_3\"",
          "message": "Row at position \"30482\" violates the foreign key: for \"id_desdobramento_3\": values \"4020\" not found in the lookup table \"dm_desdobramento_3_rec\" as \"id_desdobramento_3\"",
          "description": "Values in the foreign key fields should exist in the reference table"
        },
        {
          "cells": [
            "1002",
            "4224",
            "544",
            "802",
            "974",
            "2129",
            "4054",
            "7469",
            "15947",
            "16794",
            "4",
            "23",
            "9118022402000",
            "2022",
            "-1751.40"
          ],
          "rowNumber": 31092,
          "rowPosition": 31093,
          "code": "foreign-key-error",
          "name": "ForeignKey Error",
          "tags": [
            "#table",
            "#row"
          ],
          "note": "for \"id_desdobramento_3\": values \"4054\" not found in the lookup table \"dm_desdobramento_3_rec\" as \"id_desdobramento_3\"",
          "message": "Row at position \"31093\" violates the foreign key: for \"id_desdobramento_3\": values \"4054\" not found in the lookup table \"dm_desdobramento_3_rec\" as \"id_desdobramento_3\"",
          "description": "Values in the foreign key fields should exist in the reference table"
        },
        {
          "cells": [
            "1002",
            "4224",
            "544",
            "802",
            "974",
            "2129",
            "4054",
            "7469",
            "15947",
            "16794",
            "4",
            "23",
            "9118022402000",
            "2022",
            "-1751.40"
          ],
          "rowNumber": 31092,
          "rowPosition": 31093,
          "code": "foreign-key-error",
          "name": "ForeignKey Error",
          "tags": [
            "#table",
            "#row"
          ],
          "note": "for \"id_desdobramento_2\": values \"2129\" not found in the lookup table \"dm_desdobramento_2_rec\" as \"id_desdobramento_2\"",
          "message": "Row at position \"31093\" violates the foreign key: for \"id_desdobramento_2\": values \"2129\" not found in the lookup table \"dm_desdobramento_2_rec\" as \"id_desdobramento_2\"",
          "description": "Values in the foreign key fields should exist in the reference table"
        },
        {
          "cells": [
            "994",
            "4144",
            "528",
            "50",
            "963",
            "2112",
            "4025",
            "7432",
            "15651",
            "16365",
            "4",
            "23",
            "9118022102000",
            "2021",
            "-14588725.34"
          ],
          "rowNumber": 31097,
          "rowPosition": 31098,
          "code": "foreign-key-error",
          "name": "ForeignKey Error",
          "tags": [
            "#table",
            "#row"
          ],
          "note": "for \"id_desdobramento_3\": values \"4025\" not found in the lookup table \"dm_desdobramento_3_rec\" as \"id_desdobramento_3\"",
          "message": "Row at position \"31098\" violates the foreign key: for \"id_desdobramento_3\": values \"4025\" not found in the lookup table \"dm_desdobramento_3_rec\" as \"id_desdobramento_3\"",
          "description": "Values in the foreign key fields should exist in the reference table"
        },
        {
          "cells": [
            "994",
            "4144",
            "528",
            "50",
            "963",
            "2112",
            "4025",
            "7432",
            "15651",
            "16365",
            "4",
            "23",
            "9118022102000",
            "2021",
            "-14588725.34"
          ],
          "rowNumber": 31097,
          "rowPosition": 31098,
          "code": "foreign-key-error",
          "name": "ForeignKey Error",
          "tags": [
            "#table",
            "#row"
          ],
          "note": "for \"id_desdobramento_2\": values \"2112\" not found in the lookup table \"dm_desdobramento_2_rec\" as \"id_desdobramento_2\"",
          "message": "Row at position \"31098\" violates the foreign key: for \"id_desdobramento_2\": values \"2112\" not found in the lookup table \"dm_desdobramento_2_rec\" as \"id_desdobramento_2\"",
          "description": "Values in the foreign key fields should exist in the reference table"
        },
        {
          "cells": [
            "994",
            "4144",
            "528",
            "50",
            "963",
            "2112",
            "4025",
            "7430",
            "15648",
            "16364",
            "4",
            "23",
            "9118022202000",
            "2021",
            "-14332.45"
          ],
          "rowNumber": 31098,
          "rowPosition": 31099,
          "code": "foreign-key-error",
          "name": "ForeignKey Error",
          "tags": [
            "#table",
            "#row"
          ],
          "note": "for \"id_desdobramento_3\": values \"4025\" not found in the lookup table \"dm_desdobramento_3_rec\" as \"id_desdobramento_3\"",
          "message": "Row at position \"31099\" violates the foreign key: for \"id_desdobramento_3\": values \"4025\" not found in the lookup table \"dm_desdobramento_3_rec\" as \"id_desdobramento_3\"",
          "description": "Values in the foreign key fields should exist in the reference table"
        },
        {
          "cells": [
            "994",
            "4144",
            "528",
            "50",
            "963",
            "2112",
            "4025",
            "7430",
            "15648",
            "16364",
            "4",
            "23",
            "9118022202000",
            "2021",
            "-14332.45"
          ],
          "rowNumber": 31098,
          "rowPosition": 31099,
          "code": "foreign-key-error",
          "name": "ForeignKey Error",
          "tags": [
            "#table",
            "#row"
          ],
          "note": "for \"id_desdobramento_2\": values \"2112\" not found in the lookup table \"dm_desdobramento_2_rec\" as \"id_desdobramento_2\"",
          "message": "Row at position \"31099\" violates the foreign key: for \"id_desdobramento_2\": values \"2112\" not found in the lookup table \"dm_desdobramento_2_rec\" as \"id_desdobramento_2\"",
          "description": "Values in the foreign key fields should exist in the reference table"
        },
        {
          "cells": [
            "999",
            "4224",
            "541",
            "799",
            "971",
            "2125",
            "4048",
            "7468",
            "15939",
            "16782",
            "54",
            "20",
            "9118012302000",
            "2022",
            "-4831061.90"
          ],
          "rowNumber": 31409,
          "rowPosition": 31410,
          "code": "foreign-key-error",
          "name": "ForeignKey Error",
          "tags": [
            "#table",
            "#row"
          ],
          "note": "for \"id_desdobramento_3\": values \"4048\" not found in the lookup table \"dm_desdobramento_3_rec\" as \"id_desdobramento_3\"",
          "message": "Row at position \"31410\" violates the foreign key: for \"id_desdobramento_3\": values \"4048\" not found in the lookup table \"dm_desdobramento_3_rec\" as \"id_desdobramento_3\"",
          "description": "Values in the foreign key fields should exist in the reference table"
        },
        {
          "cells": [
            "999",
            "4224",
            "541",
            "799",
            "971",
            "2125",
            "4048",
            "7468",
            "15939",
            "16782",
            "54",
            "20",
            "9118012302000",
            "2022",
            "-4831061.90"
          ],
          "rowNumber": 31409,
          "rowPosition": 31410,
          "code": "foreign-key-error",
          "name": "ForeignKey Error",
          "tags": [
            "#table",
            "#row"
          ],
          "note": "for \"id_desdobramento_2\": values \"2125\" not found in the lookup table \"dm_desdobramento_2_rec\" as \"id_desdobramento_2\"",
          "message": "Row at position \"31410\" violates the foreign key: for \"id_desdobramento_2\": values \"2125\" not found in the lookup table \"dm_desdobramento_2_rec\" as \"id_desdobramento_2\"",
          "description": "Values in the foreign key fields should exist in the reference table"
        },
        {
          "cells": [
            "987",
            "4113",
            "10",
            "145",
            "173",
            "437",
            "4020",
            "7427",
            "15615",
            "16001",
            "355",
            "92",
            "1718039101000",
            "2021",
            "3520204.80"
          ],
          "rowNumber": 31520,
          "rowPosition": 31521,
          "code": "foreign-key-error",
          "name": "ForeignKey Error",
          "tags": [
            "#table",
            "#row"
          ],
          "note": "for \"id_desdobramento_3\": values \"4020\" not found in the lookup table \"dm_desdobramento_3_rec\" as \"id_desdobramento_3\"",
          "message": "Row at position \"31521\" violates the foreign key: for \"id_desdobramento_3\": values \"4020\" not found in the lookup table \"dm_desdobramento_3_rec\" as \"id_desdobramento_3\"",
          "description": "Values in the foreign key fields should exist in the reference table"
        },
        {
          "cells": [
            "975",
            "4032",
            "10",
            "145",
            "173",
            "437",
            "4020",
            "7427",
            "15615",
            "16001",
            "355",
            "92",
            "1718039101000",
            "2020",
            "33379000.00"
          ],
          "rowNumber": 31627,
          "rowPosition": 31628,
          "code": "foreign-key-error",
          "name": "ForeignKey Error",
          "tags": [
            "#table",
            "#row"
          ],
          "note": "for \"id_desdobramento_3\": values \"4020\" not found in the lookup table \"dm_desdobramento_3_rec\" as \"id_desdobramento_3\"",
          "message": "Row at position \"31628\" violates the foreign key: for \"id_desdobramento_3\": values \"4020\" not found in the lookup table \"dm_desdobramento_3_rec\" as \"id_desdobramento_3\"",
          "description": "Values in the foreign key fields should exist in the reference table"
        },
        {
          "cells": [
            "980",
            "4032",
            "10",
            "145",
            "173",
            "437",
            "4020",
            "7427",
            "15615",
            "16001",
            "355",
            "92",
            "1718039101000",
            "2020",
            "9064577.96"
          ],
          "rowNumber": 32640,
          "rowPosition": 32641,
          "code": "foreign-key-error",
          "name": "ForeignKey Error",
          "tags": [
            "#table",
            "#row"
          ],
          "note": "for \"id_desdobramento_3\": values \"4020\" not found in the lookup table \"dm_desdobramento_3_rec\" as \"id_desdobramento_3\"",
          "message": "Row at position \"32641\" violates the foreign key: for \"id_desdobramento_3\": values \"4020\" not found in the lookup table \"dm_desdobramento_3_rec\" as \"id_desdobramento_3\"",
          "description": "Values in the foreign key fields should exist in the reference table"
        },
        {
          "cells": [
            "979",
            "4032",
            "16",
            "145",
            "173",
            "199",
            "4020",
            "7427",
            "15616",
            "15997",
            "356",
            "93",
            "2418039101000",
            "2020",
            "2437572.00"
          ],
          "rowNumber": 32641,
          "rowPosition": 32642,
          "code": "foreign-key-error",
          "name": "ForeignKey Error",
          "tags": [
            "#table",
            "#row"
          ],
          "note": "for \"id_desdobramento_3\": values \"4020\" not found in the lookup table \"dm_desdobramento_3_rec\" as \"id_desdobramento_3\"",
          "message": "Row at position \"32642\" violates the foreign key: for \"id_desdobramento_3\": values \"4020\" not found in the lookup table \"dm_desdobramento_3_rec\" as \"id_desdobramento_3\"",
          "description": "Values in the foreign key fields should exist in the reference table"
        },
        {
          "cells": [
            "976",
            "4032",
            "10",
            "145",
            "173",
            "437",
            "4020",
            "7427",
            "15615",
            "16001",
            "355",
            "92",
            "1718039101000",
            "2020",
            "5472000.00"
          ],
          "rowNumber": 32893,
          "rowPosition": 32894,
          "code": "foreign-key-error",
          "name": "ForeignKey Error",
          "tags": [
            "#table",
            "#row"
          ],
          "note": "for \"id_desdobramento_3\": values \"4020\" not found in the lookup table \"dm_desdobramento_3_rec\" as \"id_desdobramento_3\"",
          "message": "Row at position \"32894\" violates the foreign key: for \"id_desdobramento_3\": values \"4020\" not found in the lookup table \"dm_desdobramento_3_rec\" as \"id_desdobramento_3\"",
          "description": "Values in the foreign key fields should exist in the reference table"
        },
        {
          "cells": [
            "999",
            "4224",
            "531",
            "792",
            "966",
            "2118",
            "4036",
            "7447",
            "15648",
            "16364",
            "4",
            "23",
            "9118022202000",
            "2022",
            "-51399.38"
          ],
          "rowNumber": 32931,
          "rowPosition": 32932,
          "code": "foreign-key-error",
          "name": "ForeignKey Error",
          "tags": [
            "#table",
            "#row"
          ],
          "note": "for \"id_desdobramento_3\": values \"4036\" not found in the lookup table \"dm_desdobramento_3_rec\" as \"id_desdobramento_3\"",
          "message": "Row at position \"32932\" violates the foreign key: for \"id_desdobramento_3\": values \"4036\" not found in the lookup table \"dm_desdobramento_3_rec\" as \"id_desdobramento_3\"",
          "description": "Values in the foreign key fields should exist in the reference table"
        },
        {
          "cells": [
            "999",
            "4224",
            "531",
            "792",
            "966",
            "2118",
            "4036",
            "7447",
            "15648",
            "16364",
            "4",
            "23",
            "9118022202000",
            "2022",
            "-51399.38"
          ],
          "rowNumber": 32931,
          "rowPosition": 32932,
          "code": "foreign-key-error",
          "name": "ForeignKey Error",
          "tags": [
            "#table",
            "#row"
          ],
          "note": "for \"id_desdobramento_2\": values \"2118\" not found in the lookup table \"dm_desdobramento_2_rec\" as \"id_desdobramento_2\"",
          "message": "Row at position \"32932\" violates the foreign key: for \"id_desdobramento_2\": values \"2118\" not found in the lookup table \"dm_desdobramento_2_rec\" as \"id_desdobramento_2\"",
          "description": "Values in the foreign key fields should exist in the reference table"
        },
        {
          "cells": [
            "1000",
            "4247",
            "544",
            "802",
            "974",
            "2129",
            "4054",
            "7469",
            "15947",
            "16794",
            "4",
            "23",
            "9118022402000",
            "2022",
            "0.00"
          ],
          "rowNumber": 32932,
          "rowPosition": 32933,
          "code": "foreign-key-error",
          "name": "ForeignKey Error",
          "tags": [
            "#table",
            "#row"
          ],
          "note": "for \"id_desdobramento_3\": values \"4054\" not found in the lookup table \"dm_desdobramento_3_rec\" as \"id_desdobramento_3\"",
          "message": "Row at position \"32933\" violates the foreign key: for \"id_desdobramento_3\": values \"4054\" not found in the lookup table \"dm_desdobramento_3_rec\" as \"id_desdobramento_3\"",
          "description": "Values in the foreign key fields should exist in the reference table"
        },
        {
          "cells": [
            "1000",
            "4247",
            "544",
            "802",
            "974",
            "2129",
            "4054",
            "7469",
            "15947",
            "16794",
            "4",
            "23",
            "9118022402000",
            "2022",
            "0.00"
          ],
          "rowNumber": 32932,
          "rowPosition": 32933,
          "code": "foreign-key-error",
          "name": "ForeignKey Error",
          "tags": [
            "#table",
            "#row"
          ],
          "note": "for \"id_desdobramento_2\": values \"2129\" not found in the lookup table \"dm_desdobramento_2_rec\" as \"id_desdobramento_2\"",
          "message": "Row at position \"32933\" violates the foreign key: for \"id_desdobramento_2\": values \"2129\" not found in the lookup table \"dm_desdobramento_2_rec\" as \"id_desdobramento_2\"",
          "description": "Values in the foreign key fields should exist in the reference table"
        },
        {
          "cells": [
            "993",
            "4144",
            "528",
            "50",
            "963",
            "2112",
            "4025",
            "7432",
            "15651",
            "16365",
            "4",
            "23",
            "9118022102000",
            "2021",
            "-14059910.78"
          ],
          "rowNumber": 32934,
          "rowPosition": 32935,
          "code": "foreign-key-error",
          "name": "ForeignKey Error",
          "tags": [
            "#table",
            "#row"
          ],
          "note": "for \"id_desdobramento_3\": values \"4025\" not found in the lookup table \"dm_desdobramento_3_rec\" as \"id_desdobramento_3\"",
          "message": "Row at position \"32935\" violates the foreign key: for \"id_desdobramento_3\": values \"4025\" not found in the lookup table \"dm_desdobramento_3_rec\" as \"id_desdobramento_3\"",
          "description": "Values in the foreign key fields should exist in the reference table"
        },
        {
          "cells": [
            "993",
            "4144",
            "528",
            "50",
            "963",
            "2112",
            "4025",
            "7432",
            "15651",
            "16365",
            "4",
            "23",
            "9118022102000",
            "2021",
            "-14059910.78"
          ],
          "rowNumber": 32934,
          "rowPosition": 32935,
          "code": "foreign-key-error",
          "name": "ForeignKey Error",
          "tags": [
            "#table",
            "#row"
          ],
          "note": "for \"id_desdobramento_2\": values \"2112\" not found in the lookup table \"dm_desdobramento_2_rec\" as \"id_desdobramento_2\"",
          "message": "Row at position \"32935\" violates the foreign key: for \"id_desdobramento_2\": values \"2112\" not found in the lookup table \"dm_desdobramento_2_rec\" as \"id_desdobramento_2\"",
          "description": "Values in the foreign key fields should exist in the reference table"
        },
        {
          "cells": [
            "990",
            "4144",
            "528",
            "50",
            "963",
            "2112",
            "4025",
            "7431",
            "15652",
            "16362",
            "4",
            "23",
            "9118022402000",
            "2021",
            "-95.44"
          ],
          "rowNumber": 32935,
          "rowPosition": 32936,
          "code": "foreign-key-error",
          "name": "ForeignKey Error",
          "tags": [
            "#table",
            "#row"
          ],
          "note": "for \"id_desdobramento_3\": values \"4025\" not found in the lookup table \"dm_desdobramento_3_rec\" as \"id_desdobramento_3\"",
          "message": "Row at position \"32936\" violates the foreign key: for \"id_desdobramento_3\": values \"4025\" not found in the lookup table \"dm_desdobramento_3_rec\" as \"id_desdobramento_3\"",
          "description": "Values in the foreign key fields should exist in the reference table"
        },
        {
          "cells": [
            "990",
            "4144",
            "528",
            "50",
            "963",
            "2112",
            "4025",
            "7431",
            "15652",
            "16362",
            "4",
            "23",
            "9118022402000",
            "2021",
            "-95.44"
          ],
          "rowNumber": 32935,
          "rowPosition": 32936,
          "code": "foreign-key-error",
          "name": "ForeignKey Error",
          "tags": [
            "#table",
            "#row"
          ],
          "note": "for \"id_desdobramento_2\": values \"2112\" not found in the lookup table \"dm_desdobramento_2_rec\" as \"id_desdobramento_2\"",
          "message": "Row at position \"32936\" violates the foreign key: for \"id_desdobramento_2\": values \"2112\" not found in the lookup table \"dm_desdobramento_2_rec\" as \"id_desdobramento_2\"",
          "description": "Values in the foreign key fields should exist in the reference table"
        },
        {
          "cells": [
            "977",
            "4032",
            "10",
            "145",
            "173",
            "437",
            "4020",
            "7427",
            "15615",
            "16001",
            "355",
            "92",
            "1718039101000",
            "2020",
            "181435000.00"
          ],
          "rowNumber": 33661,
          "rowPosition": 33662,
          "code": "foreign-key-error",
          "name": "ForeignKey Error",
          "tags": [
            "#table",
            "#row"
          ],
          "note": "for \"id_desdobramento_3\": values \"4020\" not found in the lookup table \"dm_desdobramento_3_rec\" as \"id_desdobramento_3\"",
          "message": "Row at position \"33662\" violates the foreign key: for \"id_desdobramento_3\": values \"4020\" not found in the lookup table \"dm_desdobramento_3_rec\" as \"id_desdobramento_3\"",
          "description": "Values in the foreign key fields should exist in the reference table"
        },
        {
          "cells": [
            "979",
            "4016",
            "527",
            "75",
            "962",
            "68",
            "4021",
            "7428",
            "15618",
            "16014",
            "25",
            "60",
            "9321001101000",
            "2020",
            "5.00"
          ],
          "rowNumber": 33662,
          "rowPosition": 33663,
          "code": "foreign-key-error",
          "name": "ForeignKey Error",
          "tags": [
            "#table",
            "#row"
          ],
          "note": "for \"id_desdobramento_3\": values \"4021\" not found in the lookup table \"dm_desdobramento_3_rec\" as \"id_desdobramento_3\"",
          "message": "Row at position \"33663\" violates the foreign key: for \"id_desdobramento_3\": values \"4021\" not found in the lookup table \"dm_desdobramento_3_rec\" as \"id_desdobramento_3\"",
          "description": "Values in the foreign key fields should exist in the reference table"
        },
        {
          "cells": [
            "979",
            "4032",
            "10",
            "145",
            "173",
            "437",
            "4020",
            "7427",
            "15615",
            "16001",
            "355",
            "92",
            "1718039101000",
            "2020",
            "837242.22"
          ],
          "rowNumber": 33899,
          "rowPosition": 33900,
          "code": "foreign-key-error",
          "name": "ForeignKey Error",
          "tags": [
            "#table",
            "#row"
          ],
          "note": "for \"id_desdobramento_3\": values \"4020\" not found in the lookup table \"dm_desdobramento_3_rec\" as \"id_desdobramento_3\"",
          "message": "Row at position \"33900\" violates the foreign key: for \"id_desdobramento_3\": values \"4020\" not found in the lookup table \"dm_desdobramento_3_rec\" as \"id_desdobramento_3\"",
          "description": "Values in the foreign key fields should exist in the reference table"
        },
        {
          "cells": [
            "978",
            "4017",
            "527",
            "75",
            "962",
            "68",
            "4021",
            "7428",
            "15618",
            "16014",
            "25",
            "60",
            "9321001101000",
            "2020",
            "-9431.92"
          ],
          "rowNumber": 35025,
          "rowPosition": 35026,
          "code": "foreign-key-error",
          "name": "ForeignKey Error",
          "tags": [
            "#table",
            "#row"
          ],
          "note": "for \"id_desdobramento_3\": values \"4021\" not found in the lookup table \"dm_desdobramento_3_rec\" as \"id_desdobramento_3\"",
          "message": "Row at position \"35026\" violates the foreign key: for \"id_desdobramento_3\": values \"4021\" not found in the lookup table \"dm_desdobramento_3_rec\" as \"id_desdobramento_3\"",
          "description": "Values in the foreign key fields should exist in the reference table"
        }
      ],
      "stats": {
        "errors": 183
      },
      "valid": false
    }
  ],
  "stats": {
    "errors": 183,
    "tasks": 1
  },
  "valid": false
}