Traceback (most recent call last):
  File "c:\users\m752587\projects\age7\venv\lib\site-packages\pymysql\connections.py", line 732, in _read_bytes
    data = self._rfile.read(num_bytes)
  File "C:\Users\m752587\AppData\Local\Programs\Python\Python39\lib\socket.py", line 704, in readinto
    return self._sock.recv_into(b)
ConnectionResetError: [WinError 10054] Foi forçado o cancelamento de uma conexão existente pelo host remoto

During handling of the above exception, another exception occurred:

Traceback (most recent call last):
  File "C:\Users\m752587\projects\age7\venv\Scripts\dtamg-py-script.py", line 33, in <module>
    sys.exit(load_entry_point('dtamg-py', 'console_scripts', 'dtamg-py')())
  File "c:\users\m752587\projects\age7\venv\lib\site-packages\click\core.py", line 1128, in __call__
    return self.main(*args, **kwargs)
  File "c:\users\m752587\projects\age7\venv\lib\site-packages\click\core.py", line 1053, in main
    rv = self.invoke(ctx)
  File "c:\users\m752587\projects\age7\venv\lib\site-packages\click\core.py", line 1659, in invoke
    return _process_result(sub_ctx.command.invoke(sub_ctx))
  File "c:\users\m752587\projects\age7\venv\lib\site-packages\click\core.py", line 1659, in invoke
    return _process_result(sub_ctx.command.invoke(sub_ctx))
  File "c:\users\m752587\projects\age7\venv\lib\site-packages\click\core.py", line 1395, in invoke
    return ctx.invoke(self.callback, **ctx.params)
  File "c:\users\m752587\projects\age7\venv\lib\site-packages\click\core.py", line 754, in invoke
    return __callback(*args, **kwargs)
  File "c:\users\m752587\projects\dtamg-py\dtamg_py\full_extract.py", line 10, in full_extract_cli
    full_extract()
  File "c:\users\m752587\projects\dtamg-py\dtamg_py\utils.py", line 43, in full_extract
    extract_resources(dp.resources)
  File "c:\users\m752587\projects\dtamg-py\dtamg_py\utils.py", line 31, in extract_resources
    cursor.execute(sql_query)
  File "c:\users\m752587\projects\age7\venv\lib\site-packages\pymysql\cursors.py", line 148, in execute
    result = self._query(query)
  File "c:\users\m752587\projects\age7\venv\lib\site-packages\pymysql\cursors.py", line 310, in _query
    conn.query(q)
  File "c:\users\m752587\projects\age7\venv\lib\site-packages\pymysql\connections.py", line 548, in query
    self._affected_rows = self._read_query_result(unbuffered=unbuffered)
  File "c:\users\m752587\projects\age7\venv\lib\site-packages\pymysql\connections.py", line 775, in _read_query_result
    result.read()
  File "c:\users\m752587\projects\age7\venv\lib\site-packages\pymysql\connections.py", line 1163, in read
    self._read_result_packet(first_packet)
  File "c:\users\m752587\projects\age7\venv\lib\site-packages\pymysql\connections.py", line 1236, in _read_result_packet
    self._read_rowdata_packet()
  File "c:\users\m752587\projects\age7\venv\lib\site-packages\pymysql\connections.py", line 1270, in _read_rowdata_packet
    packet = self.connection._read_packet()
  File "c:\users\m752587\projects\age7\venv\lib\site-packages\pymysql\connections.py", line 711, in _read_packet
    recv_data = self._read_bytes(bytes_to_read)
  File "c:\users\m752587\projects\age7\venv\lib\site-packages\pymysql\connections.py", line 738, in _read_bytes
    raise err.OperationalError(
pymysql.err.OperationalError: (2013, 'Lost connection to MySQL server during query ([WinError 10054] Foi forçado o cancelamento de uma conexão existente pelo host remoto)')
