Traceback (most recent call last):
  File "C:\Users\m752587\projects\age7\scripts\python\extract-resource.py", line 13, in <module>
    extract_resource(resource.name)
  File "C:\Users\m752587\projects\age7\scripts\python\utils.py", line 19, in extract_resource
    cur.execute(sql_query)
  File "C:\Users\m752587\projects\age7\venv\lib\site-packages\pymysql\cursors.py", line 148, in execute
    result = self._query(query)
  File "C:\Users\m752587\projects\age7\venv\lib\site-packages\pymysql\cursors.py", line 310, in _query
    conn.query(q)
  File "C:\Users\m752587\projects\age7\venv\lib\site-packages\pymysql\connections.py", line 548, in query
    self._affected_rows = self._read_query_result(unbuffered=unbuffered)
  File "C:\Users\m752587\projects\age7\venv\lib\site-packages\pymysql\connections.py", line 775, in _read_query_result
    result.read()
  File "C:\Users\m752587\projects\age7\venv\lib\site-packages\pymysql\connections.py", line 1156, in read
    first_packet = self.connection._read_packet()
  File "C:\Users\m752587\projects\age7\venv\lib\site-packages\pymysql\connections.py", line 725, in _read_packet
    packet.raise_for_error()
  File "C:\Users\m752587\projects\age7\venv\lib\site-packages\pymysql\protocol.py", line 221, in raise_for_error
    err.raise_mysql_exception(self._data)
  File "C:\Users\m752587\projects\age7\venv\lib\site-packages\pymysql\err.py", line 143, in raise_mysql_exception
    raise errorclass(errno, errval)
pymysql.err.OperationalError: (1054, "Unknown column 'id_item' in 'field list'")
